Workbook

Sheet 总览
A1: 省级中小学足球赛事系统 · 10天版六人分工（优化后）
A2: 在你的两版分工基础上取长补短；原244条功能全部保留，只压缩每条的实现深度
B4: 一、结论
A5: 1 | B5: 两版都排不进10天：V1自估约477人天(约16周)，V2为8周节奏；10天×6人只有60人天。优化版的办法是“功能一条不删(原244条全部保留)，只压缩每条的实现深度”，并把完成度分成L1完整、L2标准增删改查、L3精简三级。
A6: 2 | B6: 前提是使用现成的前后端分离后台脚手架(自带登录、RBAC、文件上传、代码生成器)。如果要从零搭框架，10天不成立，建议拆成两期。
A7: 3 | B7: 大模型10天内只保留1项：政策与报名问答(精简版，优先级P2，最先砍)。报名材料预审改为规则校验(材料是否齐全、姓名与身份证是否与档案一致)，不用大模型；V1的另外8项(材料识别、导入纠错、战报、问数、遴选摘要等)全部放二期。
A8: 4 | B8: 组长就是唯一前端(成员1)。为了不让组长成为瓶颈：组长只手写5类复杂页面(运动员/教练员端、统一报名页、审核工作台、比赛录入端、通用组件)；门户官网、CMS后台、遴选页由成员6套模板完成；各后端用代码生成器自出标准页；日常站会与缺陷分派由成员2负责，组长只做范围裁决和验收。
A9: 5 | B9: 每人正好10人天、没有缓冲，所以必须配套“降级清单”和D5检查点(见“风险与砍法”)。
B11: 二、前提与需要你确认的事
A12: 1 | B12: “10天”按10个工作日、每人每天约8小时计。如果是10个日历日(含周末)，建议把全部P1功能也按L3处理。
A13: 2 | B13: 技术栈沿用V2：Vue3+Vite+TS / Spring Boot+Maven / MySQL / Redis / MinIO / Docker Compose。
A14: 3 | B14: 人天为相对估算，蓝色数字可直接修改，“分工总览”与各人工作表的“计划日”会自动更新(“每日排期”需手工同步)。
A15: 4 | B15: D1当天必须拿到7项需求结论(评分规则、审核层级等)，见“风险与砍法”第一部分。
B17: 三、完成度三级（代替“做/不做”）
A18: L1 | B18: 完整实现：主链路上、规则复杂的功能，如登录权限、报名、审核、导出、档案、比赛录入。
A19: L2 | B19: 标准增删改查：用代码生成器出页，含搜索、分页、上传，不做额外交互。
A20: L3 | B20: 精简版：功能在、机制简化，如图文直播用短轮询、人脸核验未接通时降为“现场拍照+人工确认”、站内信打开页面时拉取。
B22: 四、对两版的取舍
A23: 取V2 | B23: 按人一页；原244条原文与行号保留；前端、后端双负责人；技术栈明确。
A24: 取V1 | B24: 只合并同构度最高的5处(报名三端、内容四类、履历约19类、进球统计三组、对阵单一数据源)；任务带ID、人天、优先级、依赖、验收；风险表与备份人。
A25: 舍V1 | B25: 原表没有的新增能力(评委角色、公示期与异议、压测与评测集等)、通用审核流程引擎、动态表单设计器、8项大模型。
A26: 舍V2 | B26: 三端分别开发；验收句大量重复；无人天无优先级；前端挂名占70%。
B28: 五、阅读顺序
A29: → | B29: ①两版对比与取舍 → ②分工总览(谁做什么、人天是否均衡) → ③每日排期(一页看10天) → ④成员1~6(每人一页任务) → ⑤优化后功能框架(模块、负责人、深度、优先级) → ⑥原244功能核对(逐条查归属) → ⑦风险与砍法。

Sheet 分工总览
A1: 六人分工总览
A2: 人天与功能条数由公式自动汇总；成员代号可替换为实际姓名
A4: 成员 | B4: 岗位 | C4: 主责内容 | D4: 边界与配合 | E4: 后端人天 | F4: 前端人天 | G4: 联调人天 | H4: 管理人天 | I4: 合计人天 | J4: 后端负责原功能条数 | K4: 前端负责原功能条数 | L4: 备份人 | M4: 主要风险与应对
A5: 成员1 | B5: 组长·主前端 | C5: 前端脚手架与通用组件；手写5类复杂页：运动员/教练员端、统一报名页、审核工作台、比赛录入端；范围裁决与验收 | D5: 不做门户、CMS、遴选页、标准页(分别由成员6与各后端出)；不做日常调度(成员2) | E5: =SUMIF('成员1-组长前端'!$E$6:$E$15,"后端",'成员1-组长前端'!$F$6:$F$15) -> 0 | F5: =SUMIF('成员1-组长前端'!$E$6:$E$15,"前端",'成员1-组长前端'!$F$6:$F$15) -> 7 | G5: =SUMIF('成员1-组长前端'!$E$6:$E$15,"联调",'成员1-组长前端'!$F$6:$F$15) -> 2 | H5: =SUMIF('成员1-组长前端'!$E$6:$E$15,"管理",'成员1-组长前端'!$F$6:$F$15) -> 1 | I5: =SUM(E5:H5) -> 10 | J5: =COUNTIF(原244功能核对!$I$5:$I$248,A5) -> 0 | K5: =COUNTIF(原244功能核对!$J$5:$J$248,A5) -> 114 | L5: 成员5(录入端) | M5: 唯一前端且零缓冲：D5检查点决定是否启动降级清单；联调期成员6、成员4可临时接页
A6: 成员2 | B6: 后端技术负责人·底座 | C6: 脚手架与环境、文件服务、认证权限、组织字典、账号日志消息、人脸核验(精简)、政策问答(精简)、安全最小集、联调与部署 | D6: 主持站会、分派缺陷；不做业务域功能；为全员提供底座 | E6: =SUMIF('成员2-底座后端'!$E$6:$E$15,"后端",'成员2-底座后端'!$F$6:$F$15) -> 7.5 | F6: =SUMIF('成员2-底座后端'!$E$6:$E$15,"前端",'成员2-底座后端'!$F$6:$F$15) -> 0 | G6: =SUMIF('成员2-底座后端'!$E$6:$E$15,"联调",'成员2-底座后端'!$F$6:$F$15) -> 2 | H6: =SUMIF('成员2-底座后端'!$E$6:$E$15,"管理",'成员2-底座后端'!$F$6:$F$15) -> 0.5 | I6: =SUM(E6:H6) -> 10 | J6: =COUNTIF(原244功能核对!$I$5:$I$248,A6) -> 12 | K6: =COUNTIF(原244功能核对!$J$5:$J$248,A6) -> 11 | L6: 成员3 | M6: D1–D4的底座是全员前置：脚手架自带登录先用，文件服务D2交付，其余人先接Mock
A7: 成员3 | B7: 报名与审核后端 | C7: 统一报名引擎、多级审核(含规则预审)、批量导入、PDF/Word导出、报名统计 | D7: 向成员4取人员与球队接口，向成员5取赛事配置；与成员1联调报名页 | E7: =SUMIF('成员3-报名审核'!$E$6:$E$12,"后端",'成员3-报名审核'!$F$6:$F$12) -> 7.5 | F7: =SUMIF('成员3-报名审核'!$E$6:$E$12,"前端",'成员3-报名审核'!$F$6:$F$12) -> 0 | G7: =SUMIF('成员3-报名审核'!$E$6:$E$12,"联调",'成员3-报名审核'!$F$6:$F$12) -> 2.5 | H7: =SUMIF('成员3-报名审核'!$E$6:$E$12,"管理",'成员3-报名审核'!$F$6:$F$12) -> 0 | I7: =SUM(E7:H7) -> 10 | J7: =COUNTIF(原244功能核对!$I$5:$I$248,A7) -> 67 | K7: =COUNTIF(原244功能核对!$J$5:$J$248,A7) -> 4 | L7: 成员2 | M7: 报名截止日并发与规则反复变更：主体类型用字段区分，提交接口幂等，D9并发冒烟
A8: 成员4 | B8: 人员与球队档案后端 | C8: 数据库总设计、人员主档、球队中心、通用履历引擎、管理员档案与参赛查看、遴选档案聚合 | D8: 向成员3、成员6提供人员与球队接口；标准页自己用生成器出 | E8: =SUMIF('成员4-人员球队'!$E$6:$E$11,"后端",'成员4-人员球队'!$F$6:$F$11) -> 7.5 | F8: =SUMIF('成员4-人员球队'!$E$6:$E$11,"前端",'成员4-人员球队'!$F$6:$F$11) -> 0 | G8: =SUMIF('成员4-人员球队'!$E$6:$E$11,"联调",'成员4-人员球队'!$F$6:$F$11) -> 2.5 | H8: =SUMIF('成员4-人员球队'!$E$6:$E$11,"管理",'成员4-人员球队'!$F$6:$F$11) -> 0 | I8: =SUM(E8:H8) -> 10 | J8: =COUNTIF(原244功能核对!$I$5:$I$248,A8) -> 82 | K8: =COUNTIF(原244功能核对!$J$5:$J$248,A8) -> 49 | L8: 成员6 | M8: 按条数最多：靠履历引擎与生成器压缩；身份证唯一键与报名快照D1评审
A9: 成员5 | B9: 赛事运行与门户内容后端 | C9: 赛事配置、对阵、赛况事件流、图文直播与赛事文件、CMS与门户公开接口、榜单与统计 | D9: 录入页面由成员1做，门户页面由成员6做，本人只做接口与数据 | E9: =SUMIF('成员5-赛事门户'!$E$6:$E$12,"后端",'成员5-赛事门户'!$F$6:$F$12) -> 8 | F9: =SUMIF('成员5-赛事门户'!$E$6:$E$12,"前端",'成员5-赛事门户'!$F$6:$F$12) -> 0 | G9: =SUMIF('成员5-赛事门户'!$E$6:$E$12,"联调",'成员5-赛事门户'!$F$6:$F$12) -> 2 | H9: =SUMIF('成员5-赛事门户'!$E$6:$E$12,"管理",'成员5-赛事门户'!$F$6:$F$12) -> 0 | I9: =SUM(E9:H9) -> 10 | J9: =COUNTIF(原244功能核对!$I$5:$I$248,A9) -> 61 | K9: =COUNTIF(原244功能核对!$J$5:$J$248,A9) -> 3 | L9: 成员1 | M9: 直播与现场弱网：用短轮询；榜单由事件派生，改事件自动更新
A10: 成员6 | B10: 后端兼前端(门户·遴选) | C10: 门户官网(套模板)、遴选评分后端、公示后端、CMS后台页/遴选页/公示页、问答窗、标准页整合 | D10: 按成员1样板做页；复杂页回成员1；遴选档案来自成员4 | E10: =SUMIF('成员6-门户遴选'!$E$6:$E$12,"后端",'成员6-门户遴选'!$F$6:$F$12) -> 3 | F10: =SUMIF('成员6-门户遴选'!$E$6:$E$12,"前端",'成员6-门户遴选'!$F$6:$F$12) -> 5.5 | G10: =SUMIF('成员6-门户遴选'!$E$6:$E$12,"联调",'成员6-门户遴选'!$F$6:$F$12) -> 1.5 | H10: =SUMIF('成员6-门户遴选'!$E$6:$E$12,"管理",'成员6-门户遴选'!$F$6:$F$12) -> 0 | I10: =SUM(E10:H10) -> 10 | J10: =COUNTIF(原244功能核对!$I$5:$I$248,A10) -> 22 | K10: =COUNTIF(原244功能核对!$J$5:$J$248,A10) -> 63 | L10: 成员4 | M10: 前后端两头：D4–D6集中做遴选后端；门户先接Mock后切真实
A11: 合计 | E11: =SUM(E5:E10) -> 33.5 | F11: =SUM(F5:F10) -> 12.5 | G11: =SUM(G5:G10) -> 12.5 | H11: =SUM(H5:H10) -> 1.5 | I11: =SUM(I5:I10) -> 60 | J11: =SUM(J5:J10) -> 244 | K11: =SUM(K5:K10) -> 244
D12: 核对：合计人天 − 60(6人×10天)，应为0 | I12: =I11-60 -> 0
D13: 核对：后端负责条数合计 − 244，应为0 | J13: =J11-244 -> 0
D14: 核对：前端负责条数合计 − 244，应为0(5.1等条目前端主责记成员1) | K14: =K11-244 -> 0
A16: 说明：功能条数是原表条目数，不等于工作量——同构条目经引擎合并后工作量远小于条数，工作量以人天为准。前端负责条数里，成员2/3/4/5的条目是他们用生成器自出的标准页，由成员6统一整合。

Sheet 每日排期
A1: 每日排期（一页看10天）
A2: 由各人任务按人天顺序自动排出；“贯穿”任务(组长事务、站会与答疑)未列入；改人天后请手工同步本页
A4: 日期 | B4: 成员1 组长·主前端 | C4: 成员2 后端技术负责人·底座 | D4: 成员3 报名与审核后端 | E4: 成员4 人员与球队档案后端 | F4: 成员5 赛事运行与门户内容后端 | G4: 成员6 后端兼前端(门户·遴选) | H4: 当日验收门
A5: D1 | B5: 脚手架与角色菜单 | C5: 脚手架与环境 | D5: 接口契约·Mock 统一报名引擎 | E5: 数据库总设计 | F5: 赛事配置 | G5: 样板对接 门户官网 | H5: 全员本地能启动脚手架；ER与接口契约评审；D1需求确认(见“风险与砍法”)
A6: D2 | B6: 通用组件 | C6: 文件服务 | D6: 统一报名引擎 | E6: 人员主档 | F6: 对阵编排 | G6: 门户官网 | H6: 登录+角色菜单+文件上传可用；通用组件可复用；赛事配置只读接口、对阵接口可用
A7: D3 | B7: 运动员端·教练员端 | C7: 认证与权限 | D7: 统一报名引擎 | E7: 人员主档 球队中心 | F7: 赛况事件流 | G7: 门户官网 | H7: 人员主档可注册且身份证去重；报名引擎核心(类型/表单/快照)能提交
A8: D4 | B8: 统一报名页 | C8: 认证与权限 组织与字典后台 | D8: 多级审核与规则预审 | E8: 球队中心 | F8: 赛况事件流 | G8: 遴选评分后端 | H8: 第一条主链路：球队创建→报名提交→审核(可用Mock)；赛况可录入；权限与数据隔离可用
A9: D5 | B9: 统一报名页 | C9: 账号·日志·站内信 | D9: 多级审核与规则预审 | E9: 球队中心 通用履历引擎 | F9: 直播·链接·赛事文件 | G9: 遴选评分后端 | H9: D5检查点：P0是否落后，决定是否启动“降级清单”；多级审核、直播、文件可用
A10: D6 | B10: 审核工作台 | C10: 人脸核验(精简) | D10: 批量导入 | E10: 通用履历引擎 | F10: CMS与门户公开接口 | G10: 遴选评分后端 公示后端 | H10: 批量导入与照片匹配；履历引擎；遴选后端；人脸核验(精简)
A11: D7 | B11: 比赛录入端 | C11: 政策与报名问答(精简) | D11: PDF·Word导出 | E11: 管理员档案与参赛查看 | F11: CMS与门户公开接口 | G11: 后台页与问答窗 | H11: P0后端功能冻结(报名、审核、档案、赛况、CMS、PDF/Word完成)；管理员档案、统计、榜单、安全最小集在D8上午前收尾
A12: D8 | B12: 联调：报名与档案链路 | C12: 安全最小集 联调·部署·备份 | D12: 报名统计与导出 联调与异常场景 | E12: 管理员档案与参赛查看 联调与关系回归 | F12: 榜单与统计 | G12: 后台页与问答窗 标准页整合 | H12: 联调开始：报名链路与档案链路切真实接口；榜单完成；安全最小集
A13: D9 | B13: 回归与比赛链路联调 | C13: 联调·部署·备份 | D13: 联调与异常场景 | E13: 联调与关系回归 | F13: 联调与对账 | G13: 标准页整合 联调与修复 | H13: 比赛链路联调；P0/P1缺陷清零；权限回归；244条逐项核对
A14: D10 | B14: 验收与演示 | C14: 联调·部署·备份 | D14: 联调与异常场景 | E14: 联调与关系回归 | F14: 联调与对账 | G14: 联调与修复 | H14: 部署、初始化数据、演示、备份与回滚预案；验收签字

Sheet 成员1-组长前端
A1: 成员1｜组长·主前端
A2: 负责复杂页面和公共组件：运动员/教练员端、统一报名页、审核工作台、比赛录入端；同时是组长，只做范围裁决与验收。先搭前端框架与通用组件，再做复杂业务页面，D8起联调。
A3: 计划日由“人天”顺序累计自动计算(蓝色为可改输入)；类型“后端”含自己用生成器出的标准页；最后的“贯穿”任务不占顺序排期。
A5: 任务ID | B5: 计划日 | C5: 工作内容 | D5: 具体要做什么 | E5: 类型 | F5: 人天 | G5: 优先级 | H5: 前置/配合 | I5: 完成标准(可检验) | J5: 对应模块 | K5: 进度 | L5: 起点(人天) | M5: 终点(人天)
A6: T1-01 | B6: =IF(INT(L6)+1=ROUNDUP(M6,0),"D"&(INT(L6)+1),"D"&(INT(L6)+1)&"–D"&ROUNDUP(M6,0)) -> D1 | C6: 前端脚手架与UI规范 | D6: 基于现成后台模板(Vue3+Vite+TS)：布局、8类角色菜单与路由守卫、请求封装(统一返回/错误码)、登录页、表单与表格规范，接入成员2提供的接口文档与Mock | E6: 前端 | F6: 1 | G6: P0 | H6: 成员2的脚手架(D1上午)；成员6同步学习代码生成器 | I6: 8类角色登录后只看到各自菜单；越权路由不可达；构建通过；成员6照样板可独立做一页 | J6: 0.1 | K6: 未开始 | L6: 0 | M6: =L6+F6 -> 1
A7: T1-02 | B7: =IF(INT(L7)+1=ROUNDUP(M7,0),"D"&(INT(L7)+1),"D"&(INT(L7)+1)&"–D"&ROUNDUP(M7,0)) -> D2 | C7: 通用组件库 | D7: 批量上传(含照片裁剪)、Excel导入+逐行错误展示、审核抽屉、搜索表格模板、PDF预览与下载、通用履历表单组件 | E7: 前端 | F7: 1 | G7: P0 | H7: T1-01；成员2文件服务(D2) | I7: 每个组件有示例页；成员6与各后端可直接复用；文件过大/类型不符/上传失败均有提示 | J7: 0.3, 0.4 | K7: 未开始 | L7: =M6 -> 1 | M7: =L7+F7 -> 2
A8: T1-03 | B8: =IF(INT(L8)+1=ROUNDUP(M8,0),"D"&(INT(L8)+1),"D"&(INT(L8)+1)&"–D"&ROUNDUP(M8,0)) -> D3 | C8: 运动员端、教练员端页面 | D8: 注册、信息完善与确认、数据匹配提示、个人中心、通用履历材料表单(运动员9项、教练员约10项)、所属队伍与公示查看 | E8: 前端 | F8: 1 | G8: P0 | H8: 成员4人员主档接口(D3)；履历接口(D6)先用Mock | I8: 运动员与教练员可注册、完善信息并上传全部履历材料；同一身份证不重复建档；履历接口D8前切为真实接口 | J8: 2.1, 2.2, 2.3 | K8: 未开始 | L8: =M7 -> 2 | M8: =L8+F8 -> 3
A9: T1-04 | B9: =IF(INT(L9)+1=ROUNDUP(M9,0),"D"&(INT(L9)+1),"D"&(INT(L9)+1)&"–D"&ROUNDUP(M9,0)) -> D4–D5 | C9: 统一报名页(球队/高校/市州同一套) | D9: 赛事列表、报名表单(按主体类型显示字段)、球员单个与批量报送(Excel导入+照片ZIP)、材料上传(盖章扫描件/学籍证明)、搜索/修改/删除、PDF与Word导出、审核状态与结果查看 | E9: 前端 | F9: 2 | G9: P0 | H9: 成员3报名引擎(D3)；批量导入(D6)、PDF(D7)先用Mock | I9: 球队、高校、市州三类主体各自跑通“填表→报送球员→传材料→提交→看结果”；原上传、查询、修改、删除均可用 | J9: 4.1, 4.3 | K9: 未开始 | L9: =M8 -> 3 | M9: =L9+F9 -> 5
A10: T1-05 | B10: =IF(INT(L10)+1=ROUNDUP(M10,0),"D"&(INT(L10)+1),"D"&(INT(L10)+1)&"–D"&ROUNDUP(M10,0)) -> D6 | C10: 市州与省级审核工作台 | D10: 审核列表与筛选(队名/组别/状态)、详情(盖章扫描件与学籍材料查看下载)、通过/驳回+原因、退回重报闭环、统计与导出入口 | E10: 前端 | F10: 1 | G10: P0 | H10: 成员3多级审核(D5) | I10: 市州、省级权限正确；驳回后球队可改后重报；每一步有审核记录 | J10: 4.2, 4.3 | K10: 未开始 | L10: =M9 -> 5 | M10: =L10+F10 -> 6
A11: T1-06 | B11: =IF(INT(L11)+1=ROUNDUP(M11,0),"D"&(INT(L11)+1),"D"&(INT(L11)+1)&"–D"&ROUNDUP(M11,0)) -> D7 | C11: 赛事录入端(优先平板/手机) | D11: 对阵与裁判信息、进球与判罚录入(增改删查)、图文直播发布 | E11: 前端 | F11: 1 | G11: P0 | H11: 成员5赛况与直播接口(D4–D5) | I11: 现场3步内可录入一次进球；改错后比分与榜单同步 | J11: 5.1, 5.2, 5.4 | K11: 未开始 | L11: =M10 -> 6 | M11: =L11+F11 -> 7
A12: T1-07 | B12: =IF(INT(L12)+1=ROUNDUP(M12,0),"D"&(INT(L12)+1),"D"&(INT(L12)+1)&"–D"&ROUNDUP(M12,0)) -> D8 | C12: 报名链路与档案链路联调 | D12: D8起：①球队→市州→省级→导出PDF；②档案→公示；把Mock全部切为真实接口并记录缺陷清单 | E12: 联调 | F12: 1 | G12: P0 | H12: 全员；成员2分派缺陷 | I12: 两条链路各完整跑通一遍，缺陷有清单有责任人 | J12: — | K12: 未开始 | L12: =M11 -> 7 | M12: =L12+F12 -> 8
A13: T1-08 | B13: =IF(INT(L13)+1=ROUNDUP(M13,0),"D"&(INT(L13)+1),"D"&(INT(L13)+1)&"–D"&ROUNDUP(M13,0)) -> D9 | C13: 全角色回归与缺陷修复 | D13: 比赛链路联调(录入→直播→榜单→门户)；全角色主流程、权限按钮、加载/空态/错误提示、下载导出、常用屏幕与微信内打开 | E13: 联调 | F13: 1 | G13: P0 | H13: 成员2缺陷分派；成员5、成员6 | I13: P0/P1缺陷清零；全角色主流程无阻断 | J13: — | K13: 未开始 | L13: =M12 -> 8 | M13: =L13+F13 -> 9
A14: T1-09 | B14: =IF(INT(L14)+1=ROUNDUP(M14,0),"D"&(INT(L14)+1),"D"&(INT(L14)+1)&"–D"&ROUNDUP(M14,0)) -> D10 | C14: 验收与演示 | D14: 对照“原244功能核对”表逐条给出结论(通过/降级/待确认)；准备演示账号与数据；发布 | E14: 管理 | F14: 0.5 | G14: P0 | H14: 全员 | I14: 244条均有结论；演示脚本完整跑通 | J14: — | K14: 未开始 | L14: =M13 -> 9 | M14: =L14+F14 -> 9.5
A15: T1-10 | B15: D1–D10贯穿 | C15: 范围裁决与验收 | D15: 每日15分钟站会(由成员2主持)；需求与范围裁决；D5检查点决定是否启动“降级清单”；不参与日常缺陷分派 | E15: 管理 | F15: 0.5 | G15: P0 | H15: 成员2 | I15: 每天有站会纪要；砍深度的决定当天书面记录 | J15: — | K15: 未开始
E16: 合计 | F16: =SUM(F6:F15) -> 10

Sheet 成员2-底座后端
A1: 成员2｜后端技术负责人·底座
A2: 负责后端框架和公共能力：脚手架与环境、文件、认证权限、组织字典、账号日志消息、人脸核验(精简)、政策问答(精简)、安全最小集，以及联调与部署；主持每日站会、分派缺陷。
A3: 计划日由“人天”顺序累计自动计算(蓝色为可改输入)；类型“后端”含自己用生成器出的标准页；最后的“贯穿”任务不占顺序排期。
A5: 任务ID | B5: 计划日 | C5: 工作内容 | D5: 具体要做什么 | E5: 类型 | F5: 人天 | G5: 优先级 | H5: 前置/配合 | I5: 完成标准(可检验) | J5: 对应模块 | K5: 进度 | L5: 起点(人天) | M5: 终点(人天)
A6: T2-01 | B6: =IF(INT(L6)+1=ROUNDUP(M6,0),"D"&(INT(L6)+1),"D"&(INT(L6)+1)&"–D"&ROUNDUP(M6,0)) -> D1 | C6: 后端工程、环境与接口文档 | D6: Spring Boot+Maven多模块、代码生成器(同时出前后端标准页)、统一返回/异常/分页/校验、身份证与手机号加解密及脱敏工具类(成员4建档时直接使用，避免数据先明文入库再补救)、Docker Compose(MySQL/Redis/MinIO/Nginx)、Swagger或Apifox+Mock | E6: 后端 | F6: 1 | G6: P0 | H6: 无(D1上午交付) | I6: 全员当天能在本地启动并访问Mock；生成器可一键出一个标准页 | J6: 工程 | K6: 未开始 | L6: 0 | M6: =L6+F6 -> 1
A7: T2-02 | B7: =IF(INT(L7)+1=ROUNDUP(M7,0),"D"&(INT(L7)+1),"D"&(INT(L7)+1)&"–D"&ROUNDUP(M7,0)) -> D2 | C7: 文件与材料服务 | D7: MinIO对接；单个与批量上传；类型与大小校验；照片缩略图；私有材料受控下载链接 | E7: 后端 | F7: 1 | G7: P0 | H7: T2-01 | I7: 合法文件上传成功、非法类型被拒；未授权用户打不开报名材料 | J7: 0.4 | K7: 未开始 | L7: =M6 -> 1 | M7: =L7+F7 -> 2
A8: T2-03 | B8: =IF(INT(L8)+1=ROUNDUP(M8,0),"D"&(INT(L8)+1),"D"&(INT(L8)+1)&"–D"&ROUNDUP(M8,0)) -> D3–D4 | C8: 登录认证、角色与数据权限 | D8: 登录与Token；8类角色与菜单/按钮权限；数据权限：市州只见本市、高校只见本校、球队只见本队(服务端统一过滤)；账号停用；密码哈希 | E8: 后端 | F8: 1.5 | G8: P0 | H8: T2-01；成员4组织与字典初始数据 | I8: 改请求参数也不能跨球队、跨市州访问；有越权自动化用例 | J8: 0.1 | K8: 未开始 | L8: =M7 -> 2 | M8: =L8+F8 -> 3.5
A9: T2-04 | B9: =IF(INT(L9)+1=ROUNDUP(M9,0),"D"&(INT(L9)+1),"D"&(INT(L9)+1)&"–D"&ROUNDUP(M9,0)) -> D4 | C9: 组织机构与基础字典维护 | D9: 省-市州-学校/高校-球队组织树；组别、赛事类别、审核状态、材料类型字典维护页(生成器出页) | E9: 后端 | F9: 0.5 | G9: P0 | H9: 成员4初始数据脚本 | I9: 字典有缓存；后台可增改 | J9: 0.2 | K9: 未开始 | L9: =M8 -> 3.5 | M9: =L9+F9 -> 4
A10: T2-05 | B10: =IF(INT(L10)+1=ROUNDUP(M10,0),"D"&(INT(L10)+1),"D"&(INT(L10)+1)&"–D"&ROUNDUP(M10,0)) -> D5 | C10: 账号管理、日志审计、站内信 | D10: 账号查询/修改/删除/重置密码/启停；操作日志(AOP)、登录日志、报名日志及查询；站内信(审核结果、驳回通知、已读未读)；三项均用生成器出页 | E10: 后端 | F10: 1 | G10: P1 | H10: T2-03；成员3审核事件 | I10: 关键操作有留痕；球队只能看自己的消息；重置密码留痕 | J10: 0.5, 0.6, 0.7 | K10: 未开始 | L10: =M9 -> 4 | M10: =L10+F10 -> 5
A11: T2-06 | B11: =IF(INT(L11)+1=ROUNDUP(M11,0),"D"&(INT(L11)+1),"D"&(INT(L11)+1)&"–D"&ROUNDUP(M11,0)) -> D6 | C11: 赛事现场身份核验 | D11: 接入一个现成的人脸比对服务或SDK；保存核验结果与记录；无法识别或不符时进入人工复核；未接通则降级为“现场拍照+人工确认” | E11: 后端 | F11: 1 | G11: P2 | H11: 成员6结果页；D1确认是否必须接第三方识别 | I11: 正常、不符、无法识别三种结果均有明确提示并可人工复核 | J11: 5.6 | K11: 未开始 | L11: =M10 -> 5 | M11: =L11+F11 -> 6
A12: T2-07 | B12: =IF(INT(L12)+1=ROUNDUP(M12,0),"D"&(INT(L12)+1),"D"&(INT(L12)+1)&"–D"&ROUNDUP(M12,0)) -> D7 | C12: 唯一的大模型功能 | D12: 把已发布的政策、规程、报名指南整理成文本入库；调用一个大模型API(服务端保管密钥，一个适配类)；答案必须附政策出处，无依据时提示“未找到依据”；超时或不可用时降级为显示政策列表；不引入向量库 | E12: 后端 | F12: 1 | G12: P2 | H12: 成员5提供正式政策文本；成员6做问答窗 | I12: 回答带出处；无依据不乱答；关闭开关后主流程不受影响；身份证、照片等个人信息不送模型 | J12: 8.1 | K12: 未开始 | L12: =M11 -> 6 | M12: =L12+F12 -> 7
A13: T2-08 | B13: =IF(INT(L13)+1=ROUNDUP(M13,0),"D"&(INT(L13)+1),"D"&(INT(L13)+1)&"–D"&ROUNDUP(M13,0)) -> D8 | C13: 敏感信息保护 | D13: 复核全部接口、日志、公示、导出中的身份证/手机号脱敏与加密存储是否生效；文件私有访问复核；HTTPS配置 | E13: 后端 | F13: 0.5 | G13: P0 | H13: 成员4提供敏感字段清单 | I13: 日志与导出中看不到完整身份证号；抽查3个接口无越权 | J13: 0.8 | K13: 未开始 | L13: =M12 -> 7 | M13: =L13+F13 -> 7.5
A14: T2-09 | B14: =IF(INT(L14)+1=ROUNDUP(M14,0),"D"&(INT(L14)+1),"D"&(INT(L14)+1)&"–D"&ROUNDUP(M14,0)) -> D8–D10 | C14: 联调支持与上线 | D14: 联调日值班与缺陷分派；权限与数据隔离回归；报名提交并发冒烟(50并发)；部署、初始化账号与字典、备份恢复演练、回滚方案、操作说明 | E14: 联调 | F14: 2 | G14: P0 | H14: 全员 | I14: 可按说明从零部署并回滚；备份可恢复；回归清单全绿 | J14: — | K14: 未开始 | L14: =M13 -> 7.5 | M14: =L14+F14 -> 9.5
A15: T2-10 | B15: D1–D10贯穿 | C15: 站会主持与技术答疑 | D15: 每日站会主持；脚手架与权限答疑；缺陷分派；保证测试环境每天可访问 | E15: 管理 | F15: 0.5 | G15: P0 | H15: 组长 | I15: 测试环境每天可访问；缺陷当天有人认领 | J15: — | K15: 未开始
E16: 合计 | F16: =SUM(F6:F15) -> 10

Sheet 成员3-报名审核
A1: 成员3｜报名与审核后端
A2: 负责所有主体的报名、逐级审核、批量导入、PDF与Word导出、报名统计；审核中的“预审”用规则校验实现。先定契约与报名引擎，再做审核、导入、导出。
A3: 计划日由“人天”顺序累计自动计算(蓝色为可改输入)；类型“后端”含自己用生成器出的标准页；最后的“贯穿”任务不占顺序排期。
A5: 任务ID | B5: 计划日 | C5: 工作内容 | D5: 具体要做什么 | E5: 类型 | F5: 人天 | G5: 优先级 | H5: 前置/配合 | I5: 完成标准(可检验) | J5: 对应模块 | K5: 进度 | L5: 起点(人天) | M5: 终点(人天)
A6: T3-01 | B6: =IF(INT(L6)+1=ROUNDUP(M6,0),"D"&(INT(L6)+1),"D"&(INT(L6)+1)&"–D"&ROUNDUP(M6,0)) -> D1 | C6: 报名域接口契约与表结构 | D6: 统一字段、枚举、错误码、分页；报名与审核接口文档；按角色准备脱敏联调数据；报名域表结构评审 | E6: 后端 | F6: 0.5 | G6: P0 | H6: 成员4的ER总图(D1) | I6: 前后端按同一份契约并行；Mock可访问 | J6: 4.1 | K6: 未开始 | L6: 0 | M6: =L6+F6 -> 0.5
A7: T3-02 | B7: =IF(INT(L7)+1=ROUNDUP(M7,0),"D"&(INT(L7)+1),"D"&(INT(L7)+1)&"–D"&ROUNDUP(M7,0)) -> D1–D3 | C7: 统一报名引擎 | D7: 主体类型(中小学球队/高校/市州)用类型字段区分；报名表单与赛事列表；球员单个报送；提交时冻结报名快照；报名窗口与截止控制；搜索(队名/组别/状态)、修改、删除；提交接口幂等 | E7: 后端 | F7: 2.5 | G7: P0 | H7: 成员5赛事配置只读接口(D1)；成员4人员主档与球队(先用种子数据) | I7: 三类主体共用一套代码；截止后无法提交；之后修改个人资料不影响已提交快照 | J7: 4.1 | K7: 未开始 | L7: =M6 -> 0.5 | M7: =L7+F7 -> 3
A8: T3-03 | B8: =IF(INT(L8)+1=ROUNDUP(M8,0),"D"&(INT(L8)+1),"D"&(INT(L8)+1)&"–D"&ROUNDUP(M8,0)) -> D4–D5 | C8: 审核流转与材料齐全性校验 | D8: 球队→市州→省级、高校→省级；通过/驳回(原因)/撤回/重报；审核记录；材料齐全性规则校验(缺盖章扫描件、缺学籍材料、姓名或身份证与档案不一致)作为“预审”，不用大模型 | E8: 后端 | F8: 2 | G8: P0 | H8: T3-02；成员2站内信 | I8: 每一步有审核记录；驳回后可改后重报；缺材料给出明确提示 | J8: 0.3, 4.2 | K8: 未开始 | L8: =M7 -> 3 | M8: =L8+F8 -> 5
A9: T3-04 | B9: =IF(INT(L9)+1=ROUNDUP(M9,0),"D"&(INT(L9)+1),"D"&(INT(L9)+1)&"–D"&ROUNDUP(M9,0)) -> D6 | C9: 球员Excel批量导入与照片ZIP匹配 | D9: 模板下载、逐行校验与错误明细导出、照片按身份证命名自动匹配；球队/高校/市州共用 | E9: 后端 | F9: 1 | G9: P0 | H9: T3-02；成员2文件服务 | I9: 1000行导入给出逐行错误；未匹配照片清单可下载 | J9: 4.1 | K9: 未开始 | L9: =M8 -> 5 | M9: =L9+F9 -> 6
A10: T3-05 | B10: =IF(INT(L10)+1=ROUNDUP(M10,0),"D"&(INT(L10)+1),"D"&(INT(L10)+1)&"–D"&ROUNDUP(M10,0)) -> D7 | C10: 报名表PDF与球员信息表Word | D10: 模板化生成(中文字体)；单个与批量导出；盖章扫描件与学籍材料的上传、查看、下载接口 | E10: 后端 | F10: 1 | G10: P0 | H10: T3-02 | I10: PDF与Word可打开且内容正确；100名球员的报名表可在可接受时间内生成 | J10: 4.3 | K10: 未开始 | L10: =M9 -> 6 | M10: =L10+F10 -> 7
A11: T3-06 | B11: =IF(INT(L11)+1=ROUNDUP(M11,0),"D"&(INT(L11)+1),"D"&(INT(L11)+1)&"–D"&ROUNDUP(M11,0)) -> D8 | C11: 报名统计与导出 | D11: 市州与高校报名情况统计、全市汇总、赛事报名情况导出(生成器出页)；数据量小时同步导出 | E11: 后端 | F11: 0.5 | G11: P1 | H11: T3-02 | I11: 统计口径与明细一致；导出文件可打开 | J11: 4.4 | K11: 未开始 | L11: =M10 -> 7 | M11: =L11+F11 -> 7.5
A12: T3-07 | B12: =IF(INT(L12)+1=ROUNDUP(M12,0),"D"&(INT(L12)+1),"D"&(INT(L12)+1)&"–D"&ROUNDUP(M12,0)) -> D8–D10 | C12: 报名全链路联调 | D12: 球队、高校、市州、省级完整链路；重复提交、退回重报、截止边界、批量错误；报名提交并发冒烟 | E12: 联调 | F12: 2.5 | G12: P0 | H12: 成员1；成员2；成员4 | I12: 完整链路与异常场景全部通过 | J12: — | K12: 未开始 | L12: =M11 -> 7.5 | M12: =L12+F12 -> 10
E13: 合计 | F13: =SUM(F6:F12) -> 10

Sheet 成员4-人员球队
A1: 成员4｜人员与球队档案后端
A2: 负责数据库总设计、运动员/教练员主档、球队中心、通用履历引擎、管理员档案与参赛查看、遴选档案聚合。先建库与主档，向成员3提供人员与球队接口。
A3: 计划日由“人天”顺序累计自动计算(蓝色为可改输入)；类型“后端”含自己用生成器出的标准页；最后的“贯穿”任务不占顺序排期。
A5: 任务ID | B5: 计划日 | C5: 工作内容 | D5: 具体要做什么 | E5: 类型 | F5: 人天 | G5: 优先级 | H5: 前置/配合 | I5: 完成标准(可检验) | J5: 对应模块 | K5: 进度 | L5: 起点(人天) | M5: 终点(人天)
A6: T4-01 | B6: =IF(INT(L6)+1=ROUNDUP(M6,0),"D"&(INT(L6)+1),"D"&(INT(L6)+1)&"–D"&ROUNDUP(M6,0)) -> D1 | C6: 数据库总设计与初始化 | D6: 人员、球队、报名名单、赛事、评分的ER总图；公共字段、软删除、命名统一；建表与初始数据脚本(含字典、市州、学校)；约定统一内部ID | E6: 后端 | F6: 1 | G6: P0 | H6: 成员3、成员5、成员6细化各自表结构 | I6: ER图评审通过；空库可一键初始化；人员、球队、比赛不重复建主表 | J6: 工程 | K6: 未开始 | L6: 0 | M6: =L6+F6 -> 1
A7: T4-02 | B7: =IF(INT(L7)+1=ROUNDUP(M7,0),"D"&(INT(L7)+1),"D"&(INT(L7)+1)&"–D"&ROUNDUP(M7,0)) -> D2–D3 | C7: 运动员与教练员主档 | D7: 注册(身份证与手机号校验)、个人信息完善与确认；以身份证为唯一键去重与数据匹配合并；教练员个人中心与修改；公示字段白名单 | E7: 后端 | F7: 1.5 | G7: P0 | H7: T4-01；成员2认证 | I7: 同一身份证只有一份档案；合并留痕；运动员与教练员能注册并完善信息 | J7: 2.1, 2.3 | K7: 未开始 | L7: =M6 -> 1 | M7: =L7+F7 -> 2.5
A8: T4-03 | B8: =IF(INT(L8)+1=ROUNDUP(M8,0),"D"&(INT(L8)+1),"D"&(INT(L8)+1)&"–D"&ROUNDUP(M8,0)) -> D3–D5 | C8: 球队档案、成员、教练员 | D8: 球队创建/修改/删除/查询(队旗队徽、简介、合照)；球队成员(关联唯一人员档案、照片、按姓名/身份证搜索)；球队教练员关联(类别与审核状态筛选)；生成器出页 | E8: 后端 | F8: 2 | G8: P0 | H8: T4-02；成员2文件服务 | I8: 成员不重复存储身份信息；改个人资料不改变已提交的历史名单 | J8: 3.1, 3.2, 3.3 | K8: 未开始 | L8: =M7 -> 2.5 | M8: =L8+F8 -> 4.5
A9: T4-04 | B9: =IF(INT(L9)+1=ROUNDUP(M9,0),"D"&(INT(L9)+1),"D"&(INT(L9)+1)&"–D"&ROUNDUP(M9,0)) -> D5–D6 | C9: 履历材料(通用) | D9: 材料类型配置+附件+审核状态，覆盖运动员与教练员约19类，以及球队材料(训练计划、荣誉、参赛、对阵记录)；新增类型只改配置 | E9: 后端 | F9: 1.5 | G9: P1 | H9: T4-02；成员2文件服务 | I9: 新增一种材料类型不用新写接口；材料可查询、编辑、删除并有审核状态 | J9: 2.2, 3.2 | K9: 未开始 | L9: =M8 -> 4.5 | M9: =L9+F9 -> 6
A10: T4-05 | B10: =IF(INT(L10)+1=ROUNDUP(M10,0),"D"&(INT(L10)+1),"D"&(INT(L10)+1)&"–D"&ROUNDUP(M10,0)) -> D7–D8 | C10: 管理员端档案管理 | D10: 球员与教练员按姓名/身份证/类别/审核状态搜索、增改删、头像；参赛查看(按市州/赛事类别/队名)；遴选档案聚合(按身份证/按队伍)；生成器出页 | E10: 后端 | F10: 1.5 | G10: P1 | H10: T4-02、T4-03 | I10: 组合条件加分页可用；修改留痕；教练员搜索只保留一处接口 | J10: 2.4, 3.4, 6.1 | K10: 未开始 | L10: =M9 -> 6 | M10: =L10+F10 -> 7.5
A11: T4-06 | B11: =IF(INT(L11)+1=ROUNDUP(M11,0),"D"&(INT(L11)+1),"D"&(INT(L11)+1)&"–D"&ROUNDUP(M11,0)) -> D8–D10 | C11: 档案联调与回归 | D11: 转队与关系变更、历史快照不受影响、公示取消、删除前关联检查、敏感字段隔离；配合成员1在D8把Mock切为真实接口 | E11: 联调 | F11: 2.5 | G11: P0 | H11: 成员1；成员3；成员6 | I11: 历史资料正确；不能跨队查看私有材料 | J11: — | K11: 未开始 | L11: =M10 -> 7.5 | M11: =L11+F11 -> 10
E12: 合计 | F12: =SUM(F6:F11) -> 10

Sheet 成员5-赛事门户
A1: 成员5｜赛事运行与门户内容后端
A2: 负责赛事配置、对阵、赛况事件流、图文直播与赛事文件、CMS与门户公开接口、榜单与统计。先交赛事配置只读接口，再做比赛与门户内容。
A3: 计划日由“人天”顺序累计自动计算(蓝色为可改输入)；类型“后端”含自己用生成器出的标准页；最后的“贯穿”任务不占顺序排期。
A5: 任务ID | B5: 计划日 | C5: 工作内容 | D5: 具体要做什么 | E5: 类型 | F5: 人天 | G5: 优先级 | H5: 前置/配合 | I5: 完成标准(可检验) | J5: 对应模块 | K5: 进度 | L5: 起点(人天) | M5: 终点(人天)
A6: T5-01 | B6: =IF(INT(L6)+1=ROUNDUP(M6,0),"D"&(INT(L6)+1),"D"&(INT(L6)+1)&"–D"&ROUNDUP(M6,0)) -> D1 | C6: 赛事与组别配置 | D6: 赛事、届次、组别与名额、报名窗口与截止、资格规则参数(年龄/学籍)、赛程阶段；先交只读接口给成员3；生成器出管理页 | E6: 后端 | F6: 1 | G6: P0 | H6: T4-01 | I6: 配置可被报名与比赛读取；关闭报名后不能新提交 | J6: 1.1 | K6: 未开始 | L6: 0 | M6: =L6+F6 -> 1
A7: T5-02 | B7: =IF(INT(L7)+1=ROUNDUP(M7,0),"D"&(INT(L7)+1),"D"&(INT(L7)+1)&"–D"&ROUNDUP(M7,0)) -> D2 | C7: 对阵编排 | D7: 对阵创建/修改/删除/查询(按状态、按球队)、发布上线；对阵作为单一数据源，门户只读已发布数据 | E7: 后端 | F7: 1 | G7: P0 | H7: T5-01 | I7: 录入端与门户使用同一份对阵数据 | J7: 5.1 | K7: 未开始 | L7: =M6 -> 1 | M7: =L7+F7 -> 2
A8: T5-03 | B8: =IF(INT(L8)+1=ROUNDUP(M8,0),"D"&(INT(L8)+1),"D"&(INT(L8)+1)&"–D"&ROUNDUP(M8,0)) -> D3–D4 | C8: 赛况录入 | D8: 比赛事件表(进球/判罚/换人)；裁判员与对阵双方信息；录入/修改/删除/查看；修改与删除留痕 | E8: 后端 | F8: 2 | G8: P0 | H8: T5-02 | I8: 一场比赛从录入到比分变化可跑通；事件按时间序列存储 | J8: 5.2 | K8: 未开始 | L8: =M7 -> 2 | M8: =L8+F8 -> 4
A9: T5-04 | B9: =IF(INT(L9)+1=ROUNDUP(M9,0),"D"&(INT(L9)+1),"D"&(INT(L9)+1)&"–D"&ROUNDUP(M9,0)) -> D5 | C9: 图文直播与赛事文件 | D9: 图文直播(短轮询刷新)、直播链接管理；签到表、记录集签字确认表、裁判员报告书上传与查询(生成器出页) | E9: 后端 | F9: 1 | G9: P1 | H9: T5-03；成员2文件服务 | I9: 发布后刷新页面可见新直播；文件可上传下载 | J9: 5.3, 5.4 | K9: 未开始 | L9: =M8 -> 4 | M9: =L9+F9 -> 5
A10: T5-05 | B10: =IF(INT(L10)+1=ROUNDUP(M10,0),"D"&(INT(L10)+1),"D"&(INT(L10)+1)&"–D"&ROUNDUP(M10,0)) -> D6–D7 | C10: 内容管理引擎 | D10: 新闻、政策、精彩瞬间、最佳阵容共用一套内容表(内容类型字段区分)：发布/修改/删除/查看/上下线/置顶/按类别搜索；轮播图、新闻跳转图、合作方链接与图片；门户公开接口(免登录、简单缓存)；富文本防XSS | E10: 后端 | F10: 2 | G10: P1 | H10: 成员2文件服务 | I10: 新增内容类型只改配置；公开接口只返回已发布内容 | J10: 7.1, 7.2 | K10: 未开始 | L10: =M9 -> 5 | M10: =L10+F10 -> 7
A11: T5-06 | B11: =IF(INT(L11)+1=ROUNDUP(M11,0),"D"&(INT(L11)+1),"D"&(INT(L11)+1)&"–D"&ROUNDUP(M11,0)) -> D8 | C11: 成绩与榜单 | D11: 赛果发布/修改/删除/查看；进球榜与高校、中学、小学组进球统计(由赛况事件派生，组别为参数) | E11: 后端 | F11: 1 | G11: P1 | H11: T5-03 | I11: 修改进球事件后，比分、进球榜、三类组别统计同步更新 | J11: 5.5 | K11: 未开始 | L11: =M10 -> 7 | M11: =L11+F11 -> 8
A12: T5-07 | B12: =IF(INT(L12)+1=ROUNDUP(M12,0),"D"&(INT(L12)+1),"D"&(INT(L12)+1)&"–D"&ROUNDUP(M12,0)) -> D9–D10 | C12: 比赛—门户—榜单联调 | D12: 进球/判罚增改删、比赛状态、门户展示、分组榜单、链接与文件两端对账；赛事日演练(含断网重试) | E12: 联调 | F12: 2 | G12: P0 | H12: 成员1；成员6 | I12: 修正进球后，门户比分、进球榜、组别统计一致 | J12: — | K12: 未开始 | L12: =M11 -> 8 | M12: =L12+F12 -> 10
E13: 合计 | F13: =SUM(F6:F12) -> 10

Sheet 成员6-门户遴选
A1: 成员6｜后端兼前端(门户·遴选)
A2: 后端兼前端：门户官网(套模板)、遴选评分后端、公示后端、CMS后台页/遴选页/公示页、问答窗与标准页整合。先按成员1样板做页，D4–D6集中做遴选后端。
A3: 计划日由“人天”顺序累计自动计算(蓝色为可改输入)；类型“后端”含自己用生成器出的标准页；最后的“贯穿”任务不占顺序排期。
A5: 任务ID | B5: 计划日 | C5: 工作内容 | D5: 具体要做什么 | E5: 类型 | F5: 人天 | G5: 优先级 | H5: 前置/配合 | I5: 完成标准(可检验) | J5: 对应模块 | K5: 进度 | L5: 起点(人天) | M5: 终点(人天)
A6: T6-01 | B6: =IF(INT(L6)+1=ROUNDUP(M6,0),"D"&(INT(L6)+1),"D"&(INT(L6)+1)&"–D"&ROUNDUP(M6,0)) -> D1 | C6: 脚手架与生成器上手 | D6: 按成员1的样板完成一页“列表+新增+编辑+详情+权限”联调；约定自己负责门户、CMS、遴选与标准页整合 | E6: 前端 | F6: 0.5 | G6: P0 | H6: 成员1 | I6: 独立完成一个标准页并通过成员1检查 | J6: — | K6: 未开始 | L6: 0 | M6: =L6+F6 -> 0.5
A7: T6-02 | B7: =IF(INT(L7)+1=ROUNDUP(M7,0),"D"&(INT(L7)+1),"D"&(INT(L7)+1)&"–D"&ROUNDUP(M7,0)) -> D1–D3 | C7: 门户官网(套现成模板) | D7: 首页、新闻、政策、对阵、结果、精彩瞬间、最佳阵容、榜单、合作方、直播、公示查询；先接Mock，D8起逐页切真实接口；响应式兼顾手机 | E7: 前端 | F7: 2.5 | G7: P0 | H7: 成员5公开接口(D7)；D1确认模板与视觉 | I7: 首页首屏打开顺畅；手机可浏览；内容与后台发布一致 | J7: 5.1, 5.4, 5.5, 7.1, 7.2 | K7: 未开始 | L7: =M6 -> 0.5 | M7: =L7+F7 -> 3
A8: T6-03 | B8: =IF(INT(L8)+1=ROUNDUP(M8,0),"D"&(INT(L8)+1),"D"&(INT(L8)+1)&"–D"&ROUNDUP(M8,0)) -> D4–D6 | C8: 遴选评分 | D8: 评分模板(初选/复选用“轮次”参数)、评分录入与修改、汇总(固定加权公式)、导出Excel；按高校/中学/小学组生成最佳球员遴选结果并可追溯评分明细；规则以D1确认结果为准 | E8: 后端 | F8: 2.5 | G8: P1 | H8: 成员4遴选档案聚合；D1确认评分规则 | I8: 初选与复选互不覆盖；修改后汇总、结果、导出一致；三类结果可复算 | J8: 6.2 | K8: 未开始 | L8: =M7 -> 3 | M8: =L8+F8 -> 5.5
A9: T6-04 | B9: =IF(INT(L9)+1=ROUNDUP(M9,0),"D"&(INT(L9)+1),"D"&(INT(L9)+1)&"–D"&ROUNDUP(M9,0)) -> D6 | C9: 公示 | D9: 运动员/教练员/球队报名信息公示与取消、按组别/市州查询；身份证脱敏；字段白名单 | E9: 后端 | F9: 0.5 | G9: P1 | H9: 成员4公示字段白名单 | I9: 取消公示后门户立即不可见；公示内容身份证脱敏 | J9: 7.3 | K9: 未开始 | L9: =M8 -> 5.5 | M9: =L9+F9 -> 6
A10: T6-05 | B10: =IF(INT(L10)+1=ROUNDUP(M10,0),"D"&(INT(L10)+1),"D"&(INT(L10)+1)&"–D"&ROUNDUP(M10,0)) -> D7–D8 | C10: CMS后台页、遴选页、公示管理页、其他简单页 | D10: CMS后台(内容表单与富文本复用同一组件)、遴选评分/汇总/导出/结果页、公示管理页、人脸核验结果与人工复核页、政策问答悬浮窗 | E10: 前端 | F10: 1.5 | G10: P1 | H10: 成员5 CMS(D7)；本人T6-03、T6-04；成员2 | I10: 内容后台与门户一致；评分汇总与导出和结果一致 | J10: 5.6, 6.1, 6.2, 7.1, 7.2, 7.3, 8.1 | K10: 未开始 | L10: =M9 -> 6 | M10: =L10+F10 -> 7.5
A11: T6-06 | B11: =IF(INT(L11)+1=ROUNDUP(M11,0),"D"&(INT(L11)+1),"D"&(INT(L11)+1)&"–D"&ROUNDUP(M11,0)) -> D8–D9 | C11: 各域生成器页整合 | D11: 各后端自出的标准页(约25个)统一菜单、权限点与样式；补做较复杂的列表与详情 | E11: 前端 | F11: 1 | G11: P1 | H11: 成员2/3/4/5 | I11: 菜单与权限点无遗漏；样式统一 | J11: 0.2, 0.5, 0.6, 0.7, 1.1, 2.4, 3.x, 4.4, 5.3 | K11: 未开始 | L11: =M10 -> 7.5 | M11: =L11+F11 -> 8.5
A12: T6-07 | B12: =IF(INT(L12)+1=ROUNDUP(M12,0),"D"&(INT(L12)+1),"D"&(INT(L12)+1)&"–D"&ROUNDUP(M12,0)) -> D9–D10 | C12: 门户·CMS·遴选联调 | D12: 切换真实接口、门户适配手机、遴选与CMS回归 | E12: 联调 | F12: 1.5 | G12: P0 | H12: 全员 | I12: 本人负责页面无遗漏；遴选结果可复算 | J12: — | K12: 未开始 | L12: =M11 -> 8.5 | M12: =L12+F12 -> 10
E13: 合计 | F13: =SUM(F6:F12) -> 10

Sheet 优化后功能框架
A1: 优化后功能框架（共33个模块）
A2: 黄色底色=原表没有、本次新增的能力；其余为原244条功能合并重组后的模块。负责人、深度、优先级改这里，“原244功能核对”自动跟随
A4: 编号 | B4: 一级模块 | C4: 二级模块 | D4: 合并后功能点 | E4: 涉及角色 | F4: 后端负责人 | G4: 前端负责人 | H4: 前端方式 | I4: 完成度 | J4: 优先级 | K4: 后端任务 | L4: 前端任务 | M4: 后端完成日 | N4: 原功能点数 | O4: 对V1/V2的调整说明
A5: 0.1 | B5: 平台底座 | C5: 统一认证与权限 | D5: 登录/退出/改密；8类登录角色(球队、高校、市州、省级审核、运动员、教练员、管理员、赛事录入员)+公众(门户)；菜单与按钮权限；数据权限(市州/高校/球队行级隔离)；账号停用与密码哈希 | E5: 全部 | F5: 成员2 | G5: 成员1 | H5: 套脚手架 | I5: L1 | J5: P0 | K5: T2-03 | L5: T1-01 | M5: D4 | N5: =COUNTIF(原244功能核对!$G$5:$G$248,A5) -> 0 | O5: 原表没有统一认证与数据权限，是最大遗漏；评委不单设角色，遴选由管理员端完成(与原表一致)
A6: 0.2 | B6: 平台底座 | C6: 组织与基础字典 | D6: 市州、学校/高校、组别(小学/中学/高校)、赛事类别、审核状态、材料类型字典，后台可维护 | E6: 管理员 | F6: 成员2 | G6: 成员2 | H6: 生成器标准页 | I6: L2 | J6: P0 | K6: T2-04 | L6: T2-04 | M6: D4 | N6: =COUNTIF(原244功能核对!$G$5:$G$248,A6) -> 0 | O6: 原表多处“按市州/按组别/按审核状态”，统一为字典+通用查询；初始数据由成员4的建库脚本提供
A7: 0.3 | B7: 平台底座 | C7: 审核状态流转(精简) | D7: 状态(草稿/待审/通过/驳回/撤回)+审核记录表+驳回原因，由4.2实现，履历材料复用 | E7: 市州/省级审核 | F7: 成员3 | G7: 成员1 | H7: 通用组件(审核抽屉) | I7: L1 | J7: P0 | K7: T3-03 | L7: T1-02 | M7: D5 | N7: =COUNTIF(原244功能核对!$G$5:$G$248,A7) -> 0 | O7: V1做成通用审核工作流引擎(10人天)，10天内降为“状态字段+记录表”，不做流程可视化配置
A8: 0.4 | B8: 平台底座 | C8: 文件与材料服务 | D8: 单个/批量上传、类型与大小校验、缩略图、受控下载(私有材料授权访问) | E8: 全部 | F8: 成员2 | G8: 成员1 | H8: 通用组件(上传) | I8: L1 | J8: P0 | K8: T2-02 | L8: T1-02 | M8: D2 | N8: =COUNTIF(原244功能核对!$G$5:$G$248,A8) -> 0 | O8: 原表20多处“上传XX”全部复用此服务
A9: 0.5 | B9: 平台底座 | C9: 消息通知 | D9: 站内信：审核结果、驳回通知、已读未读 | E9: 球队等 | F9: 成员2 | G9: 成员2 | H9: 生成器标准页 | I9: L3 | J9: P1 | K9: T2-05 | L9: T2-05 | M9: D5 | N9: =COUNTIF(原244功能核对!$G$5:$G$248,A9) -> 1 | O9: 不做短信与实时推送，打开页面时拉取
A10: 0.6 | B10: 平台底座 | C10: 日志审计 | D10: 操作日志(AOP)、登录日志、报名日志，查询 | E10: 管理员/省级 | F10: 成员2 | G10: 成员2 | H10: 生成器标准页 | I10: L2 | J10: P1 | K10: T2-05 | L10: T2-05 | M10: D5 | N10: =COUNTIF(原244功能核对!$G$5:$G$248,A10) -> 3 | O10: 原“报名日志”与“日志管理”合并为一套
A11: 0.7 | B11: 平台底座 | C11: 账号管理 | D11: 报名账号查询/修改/删除；球队、球员、教练员账号密码重置与启停 | E11: 管理员/省级 | F11: 成员2 | G11: 成员2 | H11: 生成器标准页 | I11: L2 | J11: P1 | K11: T2-05 | L11: T2-05 | M11: D5 | N11: =COUNTIF(原244功能核对!$G$5:$G$248,A11) -> 7 | O11: 原表三个端分别出现“重置密码”，统一收口；与认证放在同一人手里减少对接
A12: 0.8 | B12: 平台底座 | C12: 安全合规(最小集) | D12: 身份证/手机号加密存储与脱敏展示(列表、日志、公示、导出)；文件私有访问；HTTPS | E12: 全部 | F12: 成员2 | G12: — | H12: — | I12: L2 | J12: P0 | K12: T2-08 | L12: — | M12: D8 | N12: =COUNTIF(原244功能核对!$G$5:$G$248,A12) -> 0 | O12: 涉及大量未成年人信息，必须补；加解密工具类D1随脚手架交付，D8做全面复核；压测、等保、漏洞扫描放二期
A13: 1.1 | B13: 赛事配置 | C13: 赛事与组别配置 | D13: 赛事创建、届次、组别与名额、报名窗口与截止、资格规则参数、赛程阶段 | E13: 省级管理员 | F13: 成员5 | G13: 成员5 | H13: 生成器标准页 | I13: L2 | J13: P0 | K13: T5-01 | L13: T5-01 | M13: D1 | N13: =COUNTIF(原244功能核对!$G$5:$G$248,A13) -> 0 | O13: 原表多处“赛事列表信息”，却没有创建赛事的来源功能；先交只读接口给报名
A14: 2.1 | B14: 人员档案中心 | C14: 运动员档案 | D14: 注册、信息完善与确认、身份证唯一键去重与数据匹配、所属队伍 | E14: 运动员 | F14: 成员4 | G14: 成员1 | H14: 手写复杂页 | I14: L1 | J14: P0 | K14: T4-02 | L14: T1-03 | M14: D3 | N14: =COUNTIF(原244功能核对!$G$5:$G$248,A14) -> 5 | O14: 原表运动员端与球队端各维护一份球员信息，改为唯一档案+报名快照
A15: 2.2 | B15: 人员档案中心 | C15: 履历材料(通用) | D15: 材料类型+附件+审核状态，覆盖运动员与教练员约19类 | E15: 运动员/教练员 | F15: 成员4 | G15: 成员1 | H15: 手写复杂页(通用表单组件) | I15: L2 | J15: P1 | K15: T4-04 | L15: T1-03, T1-02 | M15: D6 | N15: =COUNTIF(原244功能核对!$G$5:$G$248,A15) -> 19 | O15: 约19个“上传XX”同构，做一套引擎，类型靠配置
A16: 2.3 | B16: 人员档案中心 | C16: 教练员档案 | D16: 注册、个人中心、信息完善与修改 | E16: 教练员 | F16: 成员4 | G16: 成员1 | H16: 手写复杂页 | I16: L1 | J16: P0 | K16: T4-02 | L16: T1-03 | M16: D3 | N16: =COUNTIF(原244功能核对!$G$5:$G$248,A16) -> 6 | O16: 与运动员共用人员主档
... A37: 8.1 | B37: 智能化(精简) | C37: 政策与报名问答 | D37: 基于已发布政策文本的问答，答案附出处，无依据拒答，可一键关闭 | E37: 公众/球队 | F37: 成员2 | G37: 成员6 | H37: 手写页(悬浮窗) | I37: L3 | J37: P2 | K37: T2-07 | L37: T6-05 | M37: D7 | N37: =COUNTIF(原244功能核对!$G$5:$G$248,A37) -> 0 | O37: 10天内唯一保留的大模型功能，最先砍；V1另外8项AI全部放二期
M38: 合计 | N38: =SUM(N5:N37) -> 244
M39: 核对(应为0) | N39: =N38-244 -> 0

Sheet 原244功能核对
A1: 原功能逐条核对（244条）
A2: 原文逐字保留，重复描述也保留；模块、负责人、完成度、优先级、后端完成日按“优化后功能框架”自动带出；D9–D10验收时在最后一列勾选结论
A4: 序号 | B4: 原表行号 | C4: 原大模块 | D4: 使用角色(端) | E4: 功能分组 | F4: 原功能(原文) | G4: 新模块编号 | H4: 新模块名称 | I4: 后端负责人 | J4: 前端负责人 | K4: 前端方式 | L4: 完成度 | M4: 优先级 | N4: 后端完成日 | O4: 备注 | P4: 验收结论
A5: 1 | B5: 第3行 | C5: 赛事报名模块 | D5: 球队端 | E5: 报名审核查看 | F5: 球队审核信息 | G5: 4.2 | H5: =INDEX(优化后功能框架!$C$5:$C$37,MATCH($G5,优化后功能框架!$A$5:$A$37,0)) -> 多级审核 | I5: =INDEX(优化后功能框架!$F$5:$F$37,MATCH($G5,优化后功能框架!$A$5:$A$37,0)) -> 成员3 | J5: =INDEX(优化后功能框架!$G$5:$G$37,MATCH($G5,优化后功能框架!$A$5:$A$37,0)) -> 成员1 | K5: =INDEX(优化后功能框架!$H$5:$H$37,MATCH($G5,优化后功能框架!$A$5:$A$37,0)) -> 手写复杂页 | L5: =INDEX(优化后功能框架!$I$5:$I$37,MATCH($G5,优化后功能框架!$A$5:$A$37,0)) -> L1 | M5: =INDEX(优化后功能框架!$J$5:$J$37,MATCH($G5,优化后功能框架!$A$5:$A$37,0)) -> P0 | N5: =INDEX(优化后功能框架!$M$5:$M$37,MATCH($G5,优化后功能框架!$A$5:$A$37,0)) -> D5
A6: 2 | B6: 第4行 | C6: 赛事报名模块 | D6: 球队端 | E6: 报名审核查看 | F6: 按组别查看球队报名信息公示 | G6: 7.3 | H6: =INDEX(优化后功能框架!$C$5:$C$37,MATCH($G6,优化后功能框架!$A$5:$A$37,0)) -> 公示 | I6: =INDEX(优化后功能框架!$F$5:$F$37,MATCH($G6,优化后功能框架!$A$5:$A$37,0)) -> 成员6 | J6: =INDEX(优化后功能框架!$G$5:$G$37,MATCH($G6,优化后功能框架!$A$5:$A$37,0)) -> 成员6 | K6: =INDEX(优化后功能框架!$H$5:$H$37,MATCH($G6,优化后功能框架!$A$5:$A$37,0)) -> 生成器标准页+门户页 | L6: =INDEX(优化后功能框架!$I$5:$I$37,MATCH($G6,优化后功能框架!$A$5:$A$37,0)) -> L2 | M6: =INDEX(优化后功能框架!$J$5:$J$37,MATCH($G6,优化后功能框架!$A$5:$A$37,0)) -> P1 | N6: =INDEX(优化后功能框架!$M$5:$M$37,MATCH($G6,优化后功能框架!$A$5:$A$37,0)) -> D6
A7: 3 | B7: 第5行 | C7: 赛事报名模块 | D7: 球队端 | E7: 报名审核查看 | F7: 按市州查看球队报名信息公示 | G7: 7.3 | H7: =INDEX(优化后功能框架!$C$5:$C$37,MATCH($G7,优化后功能框架!$A$5:$A$37,0)) -> 公示 | I7: =INDEX(优化后功能框架!$F$5:$F$37,MATCH($G7,优化后功能框架!$A$5:$A$37,0)) -> 成员6 | J7: =INDEX(优化后功能框架!$G$5:$G$37,MATCH($G7,优化后功能框架!$A$5:$A$37,0)) -> 成员6 | K7: =INDEX(优化后功能框架!$H$5:$H$37,MATCH($G7,优化后功能框架!$A$5:$A$37,0)) -> 生成器标准页+门户页 | L7: =INDEX(优化后功能框架!$I$5:$I$37,MATCH($G7,优化后功能框架!$A$5:$A$37,0)) -> L2 | M7: =INDEX(优化后功能框架!$J$5:$J$37,MATCH($G7,优化后功能框架!$A$5:$A$37,0)) -> P1 | N7: =INDEX(优化后功能框架!$M$5:$M$37,MATCH($G7,优化后功能框架!$A$5:$A$37,0)) -> D6
A8: 4 | B8: 第6行 | C8: 赛事报名模块 | D8: 球队端 | E8: 球队报名信息报送 | F8: 赛事列表信息 | G8: 4.1 | H8: =INDEX(优化后功能框架!$C$5:$C$37,MATCH($G8,优化后功能框架!$A$5:$A$37,0)) -> 统一报名引擎 | I8: =INDEX(优化后功能框架!$F$5:$F$37,MATCH($G8,优化后功能框架!$A$5:$A$37,0)) -> 成员3 | J8: =INDEX(优化后功能框架!$G$5:$G$37,MATCH($G8,优化后功能框架!$A$5:$A$37,0)) -> 成员1 | K8: =INDEX(优化后功能框架!$H$5:$H$37,MATCH($G8,优化后功能框架!$A$5:$A$37,0)) -> 手写复杂页 | L8: =INDEX(优化后功能框架!$I$5:$I$37,MATCH($G8,优化后功能框架!$A$5:$A$37,0)) -> L1 | M8: =INDEX(优化后功能框架!$J$5:$J$37,MATCH($G8,优化后功能框架!$A$5:$A$37,0)) -> P0 | N8: =INDEX(优化后功能框架!$M$5:$M$37,MATCH($G8,优化后功能框架!$A$5:$A$37,0)) -> D6
A9: 5 | B9: 第7行 | C9: 赛事报名模块 | D9: 球队端 | E9: 球队报名信息报送 | F9: 赛事报名表单 | G9: 4.1 | H9: =INDEX(优化后功能框架!$C$5:$C$37,MATCH($G9,优化后功能框架!$A$5:$A$37,0)) -> 统一报名引擎 | I9: =INDEX(优化后功能框架!$F$5:$F$37,MATCH($G9,优化后功能框架!$A$5:$A$37,0)) -> 成员3 | J9: =INDEX(优化后功能框架!$G$5:$G$37,MATCH($G9,优化后功能框架!$A$5:$A$37,0)) -> 成员1 | K9: =INDEX(优化后功能框架!$H$5:$H$37,MATCH($G9,优化后功能框架!$A$5:$A$37,0)) -> 手写复杂页 | L9: =INDEX(优化后功能框架!$I$5:$I$37,MATCH($G9,优化后功能框架!$A$5:$A$37,0)) -> L1 | M9: =INDEX(优化后功能框架!$J$5:$J$37,MATCH($G9,优化后功能框架!$A$5:$A$37,0)) -> P0 | N9: =INDEX(优化后功能框架!$M$5:$M$37,MATCH($G9,优化后功能框架!$A$5:$A$37,0)) -> D6
A10: 6 | B10: 第8行 | C10: 赛事报名模块 | D10: 球队端 | E10: 球队报名信息报送 | F10: 填写赛事报名表单 | G10: 4.1 | H10: =INDEX(优化后功能框架!$C$5:$C$37,MATCH($G10,优化后功能框架!$A$5:$A$37,0)) -> 统一报名引擎 | I10: =INDEX(优化后功能框架!$F$5:$F$37,MATCH($G10,优化后功能框架!$A$5:$A$37,0)) -> 成员3 | J10: =INDEX(优化后功能框架!$G$5:$G$37,MATCH($G10,优化后功能框架!$A$5:$A$37,0)) -> 成员1 | K10: =INDEX(优化后功能框架!$H$5:$H$37,MATCH($G10,优化后功能框架!$A$5:$A$37,0)) -> 手写复杂页 | L10: =INDEX(优化后功能框架!$I$5:$I$37,MATCH($G10,优化后功能框架!$A$5:$A$37,0)) -> L1 | M10: =INDEX(优化后功能框架!$J$5:$J$37,MATCH($G10,优化后功能框架!$A$5:$A$37,0)) -> P0 | N10: =INDEX(优化后功能框架!$M$5:$M$37,MATCH($G10,优化后功能框架!$A$5:$A$37,0)) -> D6
A11: 7 | B11: 第9行 | C11: 赛事报名模块 | D11: 球队端 | E11: 球队报名信息报送 | F11: 报送球员信息 | G11: 4.1 | H11: =INDEX(优化后功能框架!$C$5:$C$37,MATCH($G11,优化后功能框架!$A$5:$A$37,0)) -> 统一报名引擎 | I11: =INDEX(优化后功能框架!$F$5:$F$37,MATCH($G11,优化后功能框架!$A$5:$A$37,0)) -> 成员3 | J11: =INDEX(优化后功能框架!$G$5:$G$37,MATCH($G11,优化后功能框架!$A$5:$A$37,0)) -> 成员1 | K11: =INDEX(优化后功能框架!$H$5:$H$37,MATCH($G11,优化后功能框架!$A$5:$A$37,0)) -> 手写复杂页 | L11: =INDEX(优化后功能框架!$I$5:$I$37,MATCH($G11,优化后功能框架!$A$5:$A$37,0)) -> L1 | M11: =INDEX(优化后功能框架!$J$5:$J$37,MATCH($G11,优化后功能框架!$A$5:$A$37,0)) -> P0 | N11: =INDEX(优化后功能框架!$M$5:$M$37,MATCH($G11,优化后功能框架!$A$5:$A$37,0)) -> D6
A12: 8 | B12: 第10行 | C12: 赛事报名模块 | D12: 球队端 | E12: 球队报名信息报送 | F12: 球员信息批量上传 | G12: 4.1 | H12: =INDEX(优化后功能框架!$C$5:$C$37,MATCH($G12,优化后功能框架!$A$5:$A$37,0)) -> 统一报名引擎 | I12: =INDEX(优化后功能框架!$F$5:$F$37,MATCH($G12,优化后功能框架!$A$5:$A$37,0)) -> 成员3 | J12: =INDEX(优化后功能框架!$G$5:$G$37,MATCH($G12,优化后功能框架!$A$5:$A$37,0)) -> 成员1 | K12: =INDEX(优化后功能框架!$H$5:$H$37,MATCH($G12,优化后功能框架!$A$5:$A$37,0)) -> 手写复杂页 | L12: =INDEX(优化后功能框架!$I$5:$I$37,MATCH($G12,优化后功能框架!$A$5:$A$37,0)) -> L1 | M12: =INDEX(优化后功能框架!$J$5:$J$37,MATCH($G12,优化后功能框架!$A$5:$A$37,0)) -> P0 | N12: =INDEX(优化后功能框架!$M$5:$M$37,MATCH($G12,优化后功能框架!$A$5:$A$37,0)) -> D6
A13: 9 | B13: 第11行 | C13: 赛事报名模块 | D13: 球队端 | E13: 球队报名信息报送 | F13: 球员照片信息 | G13: 4.1 | H13: =INDEX(优化后功能框架!$C$5:$C$37,MATCH($G13,优化后功能框架!$A$5:$A$37,0)) -> 统一报名引擎 | I13: =INDEX(优化后功能框架!$F$5:$F$37,MATCH($G13,优化后功能框架!$A$5:$A$37,0)) -> 成员3 | J13: =INDEX(优化后功能框架!$G$5:$G$37,MATCH($G13,优化后功能框架!$A$5:$A$37,0)) -> 成员1 | K13: =INDEX(优化后功能框架!$H$5:$H$37,MATCH($G13,优化后功能框架!$A$5:$A$37,0)) -> 手写复杂页 | L13: =INDEX(优化后功能框架!$I$5:$I$37,MATCH($G13,优化后功能框架!$A$5:$A$37,0)) -> L1 | M13: =INDEX(优化后功能框架!$J$5:$J$37,MATCH($G13,优化后功能框架!$A$5:$A$37,0)) -> P0 | N13: =INDEX(优化后功能框架!$M$5:$M$37,MATCH($G13,优化后功能框架!$A$5:$A$37,0)) -> D6
A14: 10 | B14: 第12行 | C14: 赛事报名模块 | D14: 球队端 | E14: 球队报名信息报送 | F14: 球员照片批量上传 | G14: 4.1 | H14: =INDEX(优化后功能框架!$C$5:$C$37,MATCH($G14,优化后功能框架!$A$5:$A$37,0)) -> 统一报名引擎 | I14: =INDEX(优化后功能框架!$F$5:$F$37,MATCH($G14,优化后功能框架!$A$5:$A$37,0)) -> 成员3 | J14: =INDEX(优化后功能框架!$G$5:$G$37,MATCH($G14,优化后功能框架!$A$5:$A$37,0)) -> 成员1 | K14: =INDEX(优化后功能框架!$H$5:$H$37,MATCH($G14,优化后功能框架!$A$5:$A$37,0)) -> 手写复杂页 | L14: =INDEX(优化后功能框架!$I$5:$I$37,MATCH($G14,优化后功能框架!$A$5:$A$37,0)) -> L1 | M14: =INDEX(优化后功能框架!$J$5:$J$37,MATCH($G14,优化后功能框架!$A$5:$A$37,0)) -> P0 | N14: =INDEX(优化后功能框架!$M$5:$M$37,MATCH($G14,优化后功能框架!$A$5:$A$37,0)) -> D6
A15: 11 | B15: 第13行 | C15: 赛事报名模块 | D15: 球队端 | E15: 球队报名信息报送 | F15: 按球队名称搜索球队报名信息 | G15: 4.1 | H15: =INDEX(优化后功能框架!$C$5:$C$37,MATCH($G15,优化后功能框架!$A$5:$A$37,0)) -> 统一报名引擎 | I15: =INDEX(优化后功能框架!$F$5:$F$37,MATCH($G15,优化后功能框架!$A$5:$A$37,0)) -> 成员3 | J15: =INDEX(优化后功能框架!$G$5:$G$37,MATCH($G15,优化后功能框架!$A$5:$A$37,0)) -> 成员1 | K15: =INDEX(优化后功能框架!$H$5:$H$37,MATCH($G15,优化后功能框架!$A$5:$A$37,0)) -> 手写复杂页 | L15: =INDEX(优化后功能框架!$I$5:$I$37,MATCH($G15,优化后功能框架!$A$5:$A$37,0)) -> L1 | M15: =INDEX(优化后功能框架!$J$5:$J$37,MATCH($G15,优化后功能框架!$A$5:$A$37,0)) -> P0 | N15: =INDEX(优化后功能框架!$M$5:$M$37,MATCH($G15,优化后功能框架!$A$5:$A$37,0)) -> D6
A16: 12 | B16: 第14行 | C16: 赛事报名模块 | D16: 球队端 | E16: 球队报名信息报送 | F16: 按报名组别搜索球队报名信息 | G16: 4.1 | H16: =INDEX(优化后功能框架!$C$5:$C$37,MATCH($G16,优化后功能框架!$A$5:$A$37,0)) -> 统一报名引擎 | I16: =INDEX(优化后功能框架!$F$5:$F$37,MATCH($G16,优化后功能框架!$A$5:$A$37,0)) -> 成员3 | J16: =INDEX(优化后功能框架!$G$5:$G$37,MATCH($G16,优化后功能框架!$A$5:$A$37,0)) -> 成员1 | K16: =INDEX(优化后功能框架!$H$5:$H$37,MATCH($G16,优化后功能框架!$A$5:$A$37,0)) -> 手写复杂页 | L16: =INDEX(优化后功能框架!$I$5:$I$37,MATCH($G16,优化后功能框架!$A$5:$A$37,0)) -> L1 | M16: =INDEX(优化后功能框架!$J$5:$J$37,MATCH($G16,优化后功能框架!$A$5:$A$37,0)) -> P0 | N16: =INDEX(优化后功能框架!$M$5:$M$37,MATCH($G16,优化后功能框架!$A$5:$A$37,0)) -> D6
... A70: 66 | B70: 第68行 | C70: 赛事报名模块 | D70: 省级审核端 | E70: 报名信息审核 | F70: 下载球员学籍验证材料 | G70: 4.2 | H70: =INDEX(优化后功能框架!$C$5:$C$37,MATCH($G70,优化后功能框架!$A$5:$A$37,0)) -> 多级审核 | I70: =INDEX(优化后功能框架!$F$5:$F$37,MATCH($G70,优化后功能框架!$A$5:$A$37,0)) -> 成员3 | J70: =INDEX(优化后功能框架!$G$5:$G$37,MATCH($G70,优化后功能框架!$A$5:$A$37,0)) -> 成员1 | K70: =INDEX(优化后功能框架!$H$5:$H$37,MATCH($G70,优化后功能框架!$A$5:$A$37,0)) -> 手写复杂页 | L70: =INDEX(优化后功能框架!$I$5:$I$37,MATCH($G70,优化后功能框架!$A$5:$A$37,0)) -> L1 | M70: =INDEX(优化后功能框架!$J$5:$J$37,MATCH($G70,优化后功能框架!$A$5:$A$37,0)) -> P0 | N70: =INDEX(优化后功能框架!$M$5:$M$37,MATCH($G70,优化后功能框架!$A$5:$A$37,0)) -> D5
A71: 67 | B71: 第69行 | C71: 赛事报名模块 | D71: 省级审核端 | E71: 报名信息管理 | F71: 按姓名搜索教练员报名信息 | G71: 2.4 | H71: =INDEX(优化后功能框架!$C$5:$C$37,MATCH($G71,优化后功能框架!$A$5:$A$37,0)) -> 管理员人员管理 | I71: =INDEX(优化后功能框架!$F$5:$F$37,MATCH($G71,优化后功能框架!$A$5:$A$37,0)) -> 成员4 | J71: =INDEX(优化后功能框架!$G$5:$G$37,MATCH($G71,优化后功能框架!$A$5:$A$37,0)) -> 成员4 | K71: =INDEX(优化后功能框架!$H$5:$H$37,MATCH($G71,优化后功能框架!$A$5:$A$37,0)) -> 生成器标准页 | L71: =INDEX(优化后功能框架!$I$5:$I$37,MATCH($G71,优化后功能框架!$A$5:$A$37,0)) -> L2 | M71: =INDEX(优化后功能框架!$J$5:$J$37,MATCH($G71,优化后功能框架!$A$5:$A$37,0)) -> P1 | N71: =INDEX(优化后功能框架!$M$5:$M$37,MATCH($G71,优化后功能框架!$A$5:$A$37,0)) -> D8 | O71: 原表该条在省级审核端出现两次(另见后文同名条)，保留原文，共用同一接口
A72: 68 | B72: 第70行 | C72: 赛事报名模块 | D72: 省级审核端 | E72: 报名信息管理 | F72: 按身份证搜索教练员报名信息 | G72: 2.4 | H72: =INDEX(优化后功能框架!$C$5:$C$37,MATCH($G72,优化后功能框架!$A$5:$A$37,0)) -> 管理员人员管理 | I72: =INDEX(优化后功能框架!$F$5:$F$37,MATCH($G72,优化后功能框架!$A$5:$A$37,0)) -> 成员4 | J72: =INDEX(优化后功能框架!$G$5:$G$37,MATCH($G72,优化后功能框架!$A$5:$A$37,0)) -> 成员4 | K72: =INDEX(优化后功能框架!$H$5:$H$37,MATCH($G72,优化后功能框架!$A$5:$A$37,0)) -> 生成器标准页 | L72: =INDEX(优化后功能框架!$I$5:$I$37,MATCH($G72,优化后功能框架!$A$5:$A$37,0)) -> L2 | M72: =INDEX(优化后功能框架!$J$5:$J$37,MATCH($G72,优化后功能框架!$A$5:$A$37,0)) -> P1 | N72: =INDEX(优化后功能框架!$M$5:$M$37,MATCH($G72,优化后功能框架!$A$5:$A$37,0)) -> D8 | O72: 原表该条在省级审核端出现两次(另见后文同名条)，保留原文，共用同一接口
A73: 69 | B73: 第71行 | C73: 赛事报名模块 | D73: 省级审核端 | E73: 报名信息管理 | F73: 修改教练员身份信息 | G73: 2.4 | H73: =INDEX(优化后功能框架!$C$5:$C$37,MATCH($G73,优化后功能框架!$A$5:$A$37,0)) -> 管理员人员管理 | I73: =INDEX(优化后功能框架!$F$5:$F$37,MATCH($G73,优化后功能框架!$A$5:$A$37,0)) -> 成员4 | J73: =INDEX(优化后功能框架!$G$5:$G$37,MATCH($G73,优化后功能框架!$A$5:$A$37,0)) -> 成员4 | K73: =INDEX(优化后功能框架!$H$5:$H$37,MATCH($G73,优化后功能框架!$A$5:$A$37,0)) -> 生成器标准页 | L73: =INDEX(优化后功能框架!$I$5:$I$37,MATCH($G73,优化后功能框架!$A$5:$A$37,0)) -> L2 | M73: =INDEX(优化后功能框架!$J$5:$J$37,MATCH($G73,优化后功能框架!$A$5:$A$37,0)) -> P1 | N73: =INDEX(优化后功能框架!$M$5:$M$37,MATCH($G73,优化后功能框架!$A$5:$A$37,0)) -> D8
A74: 70 | B74: 第72行 | C74: 赛事报名模块 | D74: 省级审核端 | E74: 报名信息管理 | F74: 市州报名情况统计 | G74: 4.4 | H74: =INDEX(优化后功能框架!$C$5:$C$37,MATCH($G74,优化后功能框架!$A$5:$A$37,0)) -> 报名统计与导出 | I74: =INDEX(优化后功能框架!$F$5:$F$37,MATCH($G74,优化后功能框架!$A$5:$A$37,0)) -> 成员3 | J74: =INDEX(优化后功能框架!$G$5:$G$37,MATCH($G74,优化后功能框架!$A$5:$A$37,0)) -> 成员3 | K74: =INDEX(优化后功能框架!$H$5:$H$37,MATCH($G74,优化后功能框架!$A$5:$A$37,0)) -> 生成器标准页 | L74: =INDEX(优化后功能框架!$I$5:$I$37,MATCH($G74,优化后功能框架!$A$5:$A$37,0)) -> L2 | M74: =INDEX(优化后功能框架!$J$5:$J$37,MATCH($G74,优化后功能框架!$A$5:$A$37,0)) -> P1 | N74: =INDEX(优化后功能框架!$M$5:$M$37,MATCH($G74,优化后功能框架!$A$5:$A$37,0)) -> D8
A75: 71 | B75: 第73行 | C75: 赛事报名模块 | D75: 省级审核端 | E75: 报名信息管理 | F75: 高校报名情况统计 | G75: 4.4 | H75: =INDEX(优化后功能框架!$C$5:$C$37,MATCH($G75,优化后功能框架!$A$5:$A$37,0)) -> 报名统计与导出 | I75: =INDEX(优化后功能框架!$F$5:$F$37,MATCH($G75,优化后功能框架!$A$5:$A$37,0)) -> 成员3 | J75: =INDEX(优化后功能框架!$G$5:$G$37,MATCH($G75,优化后功能框架!$A$5:$A$37,0)) -> 成员3 | K75: =INDEX(优化后功能框架!$H$5:$H$37,MATCH($G75,优化后功能框架!$A$5:$A$37,0)) -> 生成器标准页 | L75: =INDEX(优化后功能框架!$I$5:$I$37,MATCH($G75,优化后功能框架!$A$5:$A$37,0)) -> L2 | M75: =INDEX(优化后功能框架!$J$5:$J$37,MATCH($G75,优化后功能框架!$A$5:$A$37,0)) -> P1 | N75: =INDEX(优化后功能框架!$M$5:$M$37,MATCH($G75,优化后功能框架!$A$5:$A$37,0)) -> D8
A76: 72 | B76: 第77行 | C76: 赛事报名模块 | D76: 省级审核端 | E76: 报名信息管理 | F76: 按姓名搜索教练员报名信息 | G76: 2.4 | H76: =INDEX(优化后功能框架!$C$5:$C$37,MATCH($G76,优化后功能框架!$A$5:$A$37,0)) -> 管理员人员管理 | I76: =INDEX(优化后功能框架!$F$5:$F$37,MATCH($G76,优化后功能框架!$A$5:$A$37,0)) -> 成员4 | J76: =INDEX(优化后功能框架!$G$5:$G$37,MATCH($G76,优化后功能框架!$A$5:$A$37,0)) -> 成员4 | K76: =INDEX(优化后功能框架!$H$5:$H$37,MATCH($G76,优化后功能框架!$A$5:$A$37,0)) -> 生成器标准页 | L76: =INDEX(优化后功能框架!$I$5:$I$37,MATCH($G76,优化后功能框架!$A$5:$A$37,0)) -> L2 | M76: =INDEX(优化后功能框架!$J$5:$J$37,MATCH($G76,优化后功能框架!$A$5:$A$37,0)) -> P1 | N76: =INDEX(优化后功能框架!$M$5:$M$37,MATCH($G76,优化后功能框架!$A$5:$A$37,0)) -> D8 | O76: 与前面同名条目重复(原表重复)，保留原文，共用同一接口
A77: 73 | B77: 第78行 | C77: 赛事报名模块 | D77: 省级审核端 | E77: 报名信息管理 | F77: 按身份证搜索教练员报名信息 | G77: 2.4 | H77: =INDEX(优化后功能框架!$C$5:$C$37,MATCH($G77,优化后功能框架!$A$5:$A$37,0)) -> 管理员人员管理 | I77: =INDEX(优化后功能框架!$F$5:$F$37,MATCH($G77,优化后功能框架!$A$5:$A$37,0)) -> 成员4 | J77: =INDEX(优化后功能框架!$G$5:$G$37,MATCH($G77,优化后功能框架!$A$5:$A$37,0)) -> 成员4 | K77: =INDEX(优化后功能框架!$H$5:$H$37,MATCH($G77,优化后功能框架!$A$5:$A$37,0)) -> 生成器标准页 | L77: =INDEX(优化后功能框架!$I$5:$I$37,MATCH($G77,优化后功能框架!$A$5:$A$37,0)) -> L2 | M77: =INDEX(优化后功能框架!$J$5:$J$37,MATCH($G77,优化后功能框架!$A$5:$A$37,0)) -> P1 | N77: =INDEX(优化后功能框架!$M$5:$M$37,MATCH($G77,优化后功能框架!$A$5:$A$37,0)) -> D8 | O77: 与前面同名条目重复(原表重复)，保留原文，共用同一接口
A78: 74 | B78: 第79行 | C78: 赛事报名模块 | D78: 省级审核端 | E78: 报名信息管理 | F78: 上传球员头像 | G78: 2.4 | H78: =INDEX(优化后功能框架!$C$5:$C$37,MATCH($G78,优化后功能框架!$A$5:$A$37,0)) -> 管理员人员管理 | I78: =INDEX(优化后功能框架!$F$5:$F$37,MATCH($G78,优化后功能框架!$A$5:$A$37,0)) -> 成员4 | J78: =INDEX(优化后功能框架!$G$5:$G$37,MATCH($G78,优化后功能框架!$A$5:$A$37,0)) -> 成员4 | K78: =INDEX(优化后功能框架!$H$5:$H$37,MATCH($G78,优化后功能框架!$A$5:$A$37,0)) -> 生成器标准页 | L78: =INDEX(优化后功能框架!$I$5:$I$37,MATCH($G78,优化后功能框架!$A$5:$A$37,0)) -> L2 | M78: =INDEX(优化后功能框架!$J$5:$J$37,MATCH($G78,优化后功能框架!$A$5:$A$37,0)) -> P1 | N78: =INDEX(优化后功能框架!$M$5:$M$37,MATCH($G78,优化后功能框架!$A$5:$A$37,0)) -> D8
A79: 75 | B79: 第80行 | C79: 赛事报名模块 | D79: 省级审核端 | E79: 报名信息管理 | F79: 修改球员身份信息 | G79: 2.4 | H79: =INDEX(优化后功能框架!$C$5:$C$37,MATCH($G79,优化后功能框架!$A$5:$A$37,0)) -> 管理员人员管理 | I79: =INDEX(优化后功能框架!$F$5:$F$37,MATCH($G79,优化后功能框架!$A$5:$A$37,0)) -> 成员4 | J79: =INDEX(优化后功能框架!$G$5:$G$37,MATCH($G79,优化后功能框架!$A$5:$A$37,0)) -> 成员4 | K79: =INDEX(优化后功能框架!$H$5:$H$37,MATCH($G79,优化后功能框架!$A$5:$A$37,0)) -> 生成器标准页 | L79: =INDEX(优化后功能框架!$I$5:$I$37,MATCH($G79,优化后功能框架!$A$5:$A$37,0)) -> L2 | M79: =INDEX(优化后功能框架!$J$5:$J$37,MATCH($G79,优化后功能框架!$A$5:$A$37,0)) -> P1 | N79: =INDEX(优化后功能框架!$M$5:$M$37,MATCH($G79,优化后功能框架!$A$5:$A$37,0)) -> D8
A80: 76 | B80: 第81行 | C80: 赛事报名模块 | D80: 省级审核端 | E80: 报名信息管理 | F80: 增加球员身份信息 | G80: 2.4 | H80: =INDEX(优化后功能框架!$C$5:$C$37,MATCH($G80,优化后功能框架!$A$5:$A$37,0)) -> 管理员人员管理 | I80: =INDEX(优化后功能框架!$F$5:$F$37,MATCH($G80,优化后功能框架!$A$5:$A$37,0)) -> 成员4 | J80: =INDEX(优化后功能框架!$G$5:$G$37,MATCH($G80,优化后功能框架!$A$5:$A$37,0)) -> 成员4 | K80: =INDEX(优化后功能框架!$H$5:$H$37,MATCH($G80,优化后功能框架!$A$5:$A$37,0)) -> 生成器标准页 | L80: =INDEX(优化后功能框架!$I$5:$I$37,MATCH($G80,优化后功能框架!$A$5:$A$37,0)) -> L2 | M80: =INDEX(优化后功能框架!$J$5:$J$37,MATCH($G80,优化后功能框架!$A$5:$A$37,0)) -> P1 | N80: =INDEX(优化后功能框架!$M$5:$M$37,MATCH($G80,优化后功能框架!$A$5:$A$37,0)) -> D8
A81: 77 | B81: 第82行 | C81: 赛事报名模块 | D81: 省级审核端 | E81: 报名信息管理 | F81: 赛事报名情况导出 | G81: 4.4 | H81: =INDEX(优化后功能框架!$C$5:$C$37,MATCH($G81,优化后功能框架!$A$5:$A$37,0)) -> 报名统计与导出 | I81: =INDEX(优化后功能框架!$F$5:$F$37,MATCH($G81,优化后功能框架!$A$5:$A$37,0)) -> 成员3 | J81: =INDEX(优化后功能框架!$G$5:$G$37,MATCH($G81,优化后功能框架!$A$5:$A$37,0)) -> 成员3 | K81: =INDEX(优化后功能框架!$H$5:$H$37,MATCH($G81,优化后功能框架!$A$5:$A$37,0)) -> 生成器标准页 | L81: =INDEX(优化后功能框架!$I$5:$I$37,MATCH($G81,优化后功能框架!$A$5:$A$37,0)) -> L2 | M81: =INDEX(优化后功能框架!$J$5:$J$37,MATCH($G81,优化后功能框架!$A$5:$A$37,0)) -> P1 | N81: =INDEX(优化后功能框架!$M$5:$M$37,MATCH($G81,优化后功能框架!$A$5:$A$37,0)) -> D8
A82: 78 | B82: 第83行 | C82: 赛事报名模块 | D82: 省级审核端 | E82: 报名账号管理 | F82: 报名账号查询 | G82: 0.7 | H82: =INDEX(优化后功能框架!$C$5:$C$37,MATCH($G82,优化后功能框架!$A$5:$A$37,0)) -> 账号管理 | I82: =INDEX(优化后功能框架!$F$5:$F$37,MATCH($G82,优化后功能框架!$A$5:$A$37,0)) -> 成员2 | J82: =INDEX(优化后功能框架!$G$5:$G$37,MATCH($G82,优化后功能框架!$A$5:$A$37,0)) -> 成员2 | K82: =INDEX(优化后功能框架!$H$5:$H$37,MATCH($G82,优化后功能框架!$A$5:$A$37,0)) -> 生成器标准页 | L82: =INDEX(优化后功能框架!$I$5:$I$37,MATCH($G82,优化后功能框架!$A$5:$A$37,0)) -> L2 | M82: =INDEX(优化后功能框架!$J$5:$J$37,MATCH($G82,优化后功能框架!$A$5:$A$37,0)) -> P1 | N82: =INDEX(优化后功能框架!$M$5:$M$37,MATCH($G82,优化后功能框架!$A$5:$A$37,0)) -> D5
A83: 79 | B83: 第84行 | C83: 赛事报名模块 | D83: 省级审核端 | E83: 报名账号管理 | F83: 报名账号修改 | G83: 0.7 | H83: =INDEX(优化后功能框架!$C$5:$C$37,MATCH($G83,优化后功能框架!$A$5:$A$37,0)) -> 账号管理 | I83: =INDEX(优化后功能框架!$F$5:$F$37,MATCH($G83,优化后功能框架!$A$5:$A$37,0)) -> 成员2 | J83: =INDEX(优化后功能框架!$G$5:$G$37,MATCH($G83,优化后功能框架!$A$5:$A$37,0)) -> 成员2 | K83: =INDEX(优化后功能框架!$H$5:$H$37,MATCH($G83,优化后功能框架!$A$5:$A$37,0)) -> 生成器标准页 | L83: =INDEX(优化后功能框架!$I$5:$I$37,MATCH($G83,优化后功能框架!$A$5:$A$37,0)) -> L2 | M83: =INDEX(优化后功能框架!$J$5:$J$37,MATCH($G83,优化后功能框架!$A$5:$A$37,0)) -> P1 | N83: =INDEX(优化后功能框架!$M$5:$M$37,MATCH($G83,优化后功能框架!$A$5:$A$37,0)) -> D5
A84: 80 | B84: 第85行 | C84: 赛事报名模块 | D84: 省级审核端 | E84: 报名账号管理 | F84: 报名账号删除 | G84: 0.7 | H84: =INDEX(优化后功能框架!$C$5:$C$37,MATCH($G84,优化后功能框架!$A$5:$A$37,0)) -> 账号管理 | I84: =INDEX(优化后功能框架!$F$5:$F$37,MATCH($G84,优化后功能框架!$A$5:$A$37,0)) -> 成员2 | J84: =INDEX(优化后功能框架!$G$5:$G$37,MATCH($G84,优化后功能框架!$A$5:$A$37,0)) -> 成员2 | K84: =INDEX(优化后功能框架!$H$5:$H$37,MATCH($G84,优化后功能框架!$A$5:$A$37,0)) -> 生成器标准页 | L84: =INDEX(优化后功能框架!$I$5:$I$37,MATCH($G84,优化后功能框架!$A$5:$A$37,0)) -> L2 | M84: =INDEX(优化后功能框架!$J$5:$J$37,MATCH($G84,优化后功能框架!$A$5:$A$37,0)) -> P1 | N84: =INDEX(优化后功能框架!$M$5:$M$37,MATCH($G84,优化后功能框架!$A$5:$A$37,0)) -> D5
A85: 81 | B85: 第86行 | C85: 赛事报名模块 | D85: 省级审核端 | E85: 报名日志管理 | F85: 管理报名日志 | G85: 0.6 | H85: =INDEX(优化后功能框架!$C$5:$C$37,MATCH($G85,优化后功能框架!$A$5:$A$37,0)) -> 日志审计 | I85: =INDEX(优化后功能框架!$F$5:$F$37,MATCH($G85,优化后功能框架!$A$5:$A$37,0)) -> 成员2 | J85: =INDEX(优化后功能框架!$G$5:$G$37,MATCH($G85,优化后功能框架!$A$5:$A$37,0)) -> 成员2 | K85: =INDEX(优化后功能框架!$H$5:$H$37,MATCH($G85,优化后功能框架!$A$5:$A$37,0)) -> 生成器标准页 | L85: =INDEX(优化后功能框架!$I$5:$I$37,MATCH($G85,优化后功能框架!$A$5:$A$37,0)) -> L2 | M85: =INDEX(优化后功能框架!$J$5:$J$37,MATCH($G85,优化后功能框架!$A$5:$A$37,0)) -> P1 | N85: =INDEX(优化后功能框架!$M$5:$M$37,MATCH($G85,优化后功能框架!$A$5:$A$37,0)) -> D5
A86: 82 | B86: 第87行 | C86: 赛事报名模块 | D86: 省级审核端 | E86: 赛事身份核验 | F86: 球员人脸核验识别 | G86: 5.6 | H86: =INDEX(优化后功能框架!$C$5:$C$37,MATCH($G86,优化后功能框架!$A$5:$A$37,0)) -> 现场身份核验(人脸) | I86: =INDEX(优化后功能框架!$F$5:$F$37,MATCH($G86,优化后功能框架!$A$5:$A$37,0)) -> 成员2 | J86: =INDEX(优化后功能框架!$G$5:$G$37,MATCH($G86,优化后功能框架!$A$5:$A$37,0)) -> 成员6 | K86: =INDEX(优化后功能框架!$H$5:$H$37,MATCH($G86,优化后功能框架!$A$5:$A$37,0)) -> 生成器标准页 | L86: =INDEX(优化后功能框架!$I$5:$I$37,MATCH($G86,优化后功能框架!$A$5:$A$37,0)) -> L3 | M86: =INDEX(优化后功能框架!$J$5:$J$37,MATCH($G86,优化后功能框架!$A$5:$A$37,0)) -> P2 | N86: =INDEX(优化后功能框架!$M$5:$M$37,MATCH($G86,优化后功能框架!$A$5:$A$37,0)) -> D6
A87: 83 | B87: 第88行 | C87: 赛事报名模块 | D87: 赛事直播 | E87: 赛事图文直播 | F87: 赛事图文直播 | G87: 5.4 | H87: =INDEX(优化后功能框架!$C$5:$C$37,MATCH($G87,优化后功能框架!$A$5:$A$37,0)) -> 赛事直播 | I87: =INDEX(优化后功能框架!$F$5:$F$37,MATCH($G87,优化后功能框架!$A$5:$A$37,0)) -> 成员5 | J87: =INDEX(优化后功能框架!$G$5:$G$37,MATCH($G87,优化后功能框架!$A$5:$A$37,0)) -> 成员1 | K87: =INDEX(优化后功能框架!$H$5:$H$37,MATCH($G87,优化后功能框架!$A$5:$A$37,0)) -> 手写复杂页(录入端发布) | L87: =INDEX(优化后功能框架!$I$5:$I$37,MATCH($G87,优化后功能框架!$A$5:$A$37,0)) -> L3 | M87: =INDEX(优化后功能框架!$J$5:$J$37,MATCH($G87,优化后功能框架!$A$5:$A$37,0)) -> P1 | N87: =INDEX(优化后功能框架!$M$5:$M$37,MATCH($G87,优化后功能框架!$A$5:$A$37,0)) -> D5
A88: 84 | B88: 第89行 | C88: 赛事报名模块 | D88: 赛事直播 | E88: 赛事信息录入 | F88: 录入比赛裁判员信息 | G88: 5.2 | H88: =INDEX(优化后功能框架!$C$5:$C$37,MATCH($G88,优化后功能框架!$A$5:$A$37,0)) -> 赛况录入 | I88: =INDEX(优化后功能框架!$F$5:$F$37,MATCH($G88,优化后功能框架!$A$5:$A$37,0)) -> 成员5 | J88: =INDEX(优化后功能框架!$G$5:$G$37,MATCH($G88,优化后功能框架!$A$5:$A$37,0)) -> 成员1 | K88: =INDEX(优化后功能框架!$H$5:$H$37,MATCH($G88,优化后功能框架!$A$5:$A$37,0)) -> 手写复杂页(录入端) | L88: =INDEX(优化后功能框架!$I$5:$I$37,MATCH($G88,优化后功能框架!$A$5:$A$37,0)) -> L1 | M88: =INDEX(优化后功能框架!$J$5:$J$37,MATCH($G88,优化后功能框架!$A$5:$A$37,0)) -> P0 | N88: =INDEX(优化后功能框架!$M$5:$M$37,MATCH($G88,优化后功能框架!$A$5:$A$37,0)) -> D4
A89: 85 | B89: 第90行 | C89: 赛事报名模块 | D89: 赛事直播 | E89: 赛事信息录入 | F89: 录入赛事对阵双方信息 | G89: 5.2 | H89: =INDEX(优化后功能框架!$C$5:$C$37,MATCH($G89,优化后功能框架!$A$5:$A$37,0)) -> 赛况录入 | I89: =INDEX(优化后功能框架!$F$5:$F$37,MATCH($G89,优化后功能框架!$A$5:$A$37,0)) -> 成员5 | J89: =INDEX(优化后功能框架!$G$5:$G$37,MATCH($G89,优化后功能框架!$A$5:$A$37,0)) -> 成员1 | K89: =INDEX(优化后功能框架!$H$5:$H$37,MATCH($G89,优化后功能框架!$A$5:$A$37,0)) -> 手写复杂页(录入端) | L89: =INDEX(优化后功能框架!$I$5:$I$37,MATCH($G89,优化后功能框架!$A$5:$A$37,0)) -> L1 | M89: =INDEX(优化后功能框架!$J$5:$J$37,MATCH($G89,优化后功能框架!$A$5:$A$37,0)) -> P0 | N89: =INDEX(优化后功能框架!$M$5:$M$37,MATCH($G89,优化后功能框架!$A$5:$A$37,0)) -> D4
... A163: 159 | B163: 第164行 | C163: 赛事管理模块 | D163: 运动员端 | E163: 运动员履历管理 | F163: 运动员上传学历证明材料 | G163: 2.2 | H163: =INDEX(优化后功能框架!$C$5:$C$37,MATCH($G163,优化后功能框架!$A$5:$A$37,0)) -> 履历材料(通用) | I163: =INDEX(优化后功能框架!$F$5:$F$37,MATCH($G163,优化后功能框架!$A$5:$A$37,0)) -> 成员4 | J163: =INDEX(优化后功能框架!$G$5:$G$37,MATCH($G163,优化后功能框架!$A$5:$A$37,0)) -> 成员1 | K163: =INDEX(优化后功能框架!$H$5:$H$37,MATCH($G163,优化后功能框架!$A$5:$A$37,0)) -> 手写复杂页(通用表单组件) | L163: =INDEX(优化后功能框架!$I$5:$I$37,MATCH($G163,优化后功能框架!$A$5:$A$37,0)) -> L2 | M163: =INDEX(优化后功能框架!$J$5:$J$37,MATCH($G163,优化后功能框架!$A$5:$A$37,0)) -> P1 | N163: =INDEX(优化后功能框架!$M$5:$M$37,MATCH($G163,优化后功能框架!$A$5:$A$37,0)) -> D6
A164: 160 | B164: 第165行 | C164: 赛事管理模块 | D164: 运动员端 | E164: 运动员履历管理 | F164: 运动员上场其他证明材料 | G164: 2.2 | H164: =INDEX(优化后功能框架!$C$5:$C$37,MATCH($G164,优化后功能框架!$A$5:$A$37,0)) -> 履历材料(通用) | I164: =INDEX(优化后功能框架!$F$5:$F$37,MATCH($G164,优化后功能框架!$A$5:$A$37,0)) -> 成员4 | J164: =INDEX(优化后功能框架!$G$5:$G$37,MATCH($G164,优化后功能框架!$A$5:$A$37,0)) -> 成员1 | K164: =INDEX(优化后功能框架!$H$5:$H$37,MATCH($G164,优化后功能框架!$A$5:$A$37,0)) -> 手写复杂页(通用表单组件) | L164: =INDEX(优化后功能框架!$I$5:$I$37,MATCH($G164,优化后功能框架!$A$5:$A$37,0)) -> L2 | M164: =INDEX(优化后功能框架!$J$5:$J$37,MATCH($G164,优化后功能框架!$A$5:$A$37,0)) -> P1 | N164: =INDEX(优化后功能框架!$M$5:$M$37,MATCH($G164,优化后功能框架!$A$5:$A$37,0)) -> D6 | O164: 原文疑似笔误(球队成员县信息→球队成员信息；运动员上场→上传)，已保留原文，待确认
A165: 161 | B165: 第166行 | C165: 赛事管理模块 | D165: 教练员端 | E165: 教练员个人信息管理 | F165: 教练员注册表单 | G165: 2.3 | H165: =INDEX(优化后功能框架!$C$5:$C$37,MATCH($G165,优化后功能框架!$A$5:$A$37,0)) -> 教练员档案 | I165: =INDEX(优化后功能框架!$F$5:$F$37,MATCH($G165,优化后功能框架!$A$5:$A$37,0)) -> 成员4 | J165: =INDEX(优化后功能框架!$G$5:$G$37,MATCH($G165,优化后功能框架!$A$5:$A$37,0)) -> 成员1 | K165: =INDEX(优化后功能框架!$H$5:$H$37,MATCH($G165,优化后功能框架!$A$5:$A$37,0)) -> 手写复杂页 | L165: =INDEX(优化后功能框架!$I$5:$I$37,MATCH($G165,优化后功能框架!$A$5:$A$37,0)) -> L1 | M165: =INDEX(优化后功能框架!$J$5:$J$37,MATCH($G165,优化后功能框架!$A$5:$A$37,0)) -> P0 | N165: =INDEX(优化后功能框架!$M$5:$M$37,MATCH($G165,优化后功能框架!$A$5:$A$37,0)) -> D3
A166: 162 | B166: 第167行 | C166: 赛事管理模块 | D166: 教练员端 | E166: 教练员个人信息管理 | F166: 填写教练员注册表单 | G166: 2.3 | H166: =INDEX(优化后功能框架!$C$5:$C$37,MATCH($G166,优化后功能框架!$A$5:$A$37,0)) -> 教练员档案 | I166: =INDEX(优化后功能框架!$F$5:$F$37,MATCH($G166,优化后功能框架!$A$5:$A$37,0)) -> 成员4 | J166: =INDEX(优化后功能框架!$G$5:$G$37,MATCH($G166,优化后功能框架!$A$5:$A$37,0)) -> 成员1 | K166: =INDEX(优化后功能框架!$H$5:$H$37,MATCH($G166,优化后功能框架!$A$5:$A$37,0)) -> 手写复杂页 | L166: =INDEX(优化后功能框架!$I$5:$I$37,MATCH($G166,优化后功能框架!$A$5:$A$37,0)) -> L1 | M166: =INDEX(优化后功能框架!$J$5:$J$37,MATCH($G166,优化后功能框架!$A$5:$A$37,0)) -> P0 | N166: =INDEX(优化后功能框架!$M$5:$M$37,MATCH($G166,优化后功能框架!$A$5:$A$37,0)) -> D3
A167: 163 | B167: 第168行 | C167: 赛事管理模块 | D167: 教练员端 | E167: 教练员个人信息管理 | F167: 教练员个人信息 | G167: 2.3 | H167: =INDEX(优化后功能框架!$C$5:$C$37,MATCH($G167,优化后功能框架!$A$5:$A$37,0)) -> 教练员档案 | I167: =INDEX(优化后功能框架!$F$5:$F$37,MATCH($G167,优化后功能框架!$A$5:$A$37,0)) -> 成员4 | J167: =INDEX(优化后功能框架!$G$5:$G$37,MATCH($G167,优化后功能框架!$A$5:$A$37,0)) -> 成员1 | K167: =INDEX(优化后功能框架!$H$5:$H$37,MATCH($G167,优化后功能框架!$A$5:$A$37,0)) -> 手写复杂页 | L167: =INDEX(优化后功能框架!$I$5:$I$37,MATCH($G167,优化后功能框架!$A$5:$A$37,0)) -> L1 | M167: =INDEX(优化后功能框架!$J$5:$J$37,MATCH($G167,优化后功能框架!$A$5:$A$37,0)) -> P0 | N167: =INDEX(优化后功能框架!$M$5:$M$37,MATCH($G167,优化后功能框架!$A$5:$A$37,0)) -> D3
...

Sheet 风险与砍法
A1: 风险、D1必须确认的事与降级清单
A2: 10天没有缓冲，砍的顺序要事先定好，而不是临时决定
A4: 一、D1当天必须拿到的需求结论（不确认就会返工）
A5: 序号 | B5: 需要确认什么 | C5: 为什么必须在D1确认 | D5: 影响模块 | E5: 确认人
A6: 1 | B6: 遴选评分规则：评分维度、权重、同分处理、初选与复选如何衔接 | C6: 决定评分汇总公式与最佳球员结果生成；原表规则不明确 | D6: 6.2 | E6: 组长
A7: 2 | B7: 审核层级与驳回重报：球队→市州→省级、高校→省级；驳回后退回哪一级、能否撤回 | C7: 决定审核状态机与记录表结构，是报名主链路核心 | D7: 0.3、4.2 | E7: 组长
A8: 3 | B8: 报名快照：提交后是否冻结；驳回后是否可改 | C8: 决定报名与人员档案的数据结构，成员3与成员4必须一致 | D8: 4.1、2.1 | E8: 成员3、4
A9: 4 | B9: 公示范围：哪些字段可公开、身份证如何脱敏 | C9: 涉及未成年人信息，公示与门户页要用同一份白名单 | D9: 7.3、0.8 | E9: 组长
A10: 5 | B10: 人脸核验是否必须接第三方识别，有无现成服务与授权协议 | C10: 决定是做“识别+人工复核”还是“拍照+人工确认” | D10: 5.6 | E10: 组长
A11: 6 | B11: 政策问答：是否已有正式政策文本；使用哪家大模型、是否允许外发 | C11: 决定8.1能否做，以及密钥与合规处理 | D11: 8.1 | E11: 组长
A12: 7 | B12: 部署环境(自有服务器/云)、域名、HTTPS与文件存放位置 | C12: 决定D8–D10的部署与备份方案 | D12: 0.8、联调 | E12: 成员2
A14: 二、降级清单（先砍深度，不砍功能；D5检查点如P0落后，按顺序执行）
A15: 顺序 | B15: 降级对象 | C15: 怎么降 | D15: 原功能是否保留 | E15: 负责人
A16: 1 | B16: 政策与报名问答(8.1) | C16: 整项暂停，不属于原244条功能；先砍它，成员2与成员6的时间回流到主链路 | D16: 不涉及 | E16: 成员2、6
A17: 2 | B17: 人脸核验(5.6) | C17: 降为“现场拍照+人工确认”，不接第三方识别，记录保留 | D17: 保留(L3) | E17: 成员2
A18: 3 | B18: 图文直播(5.4) | C18: 短轮询，不做实时推送；直播链接管理照常 | D18: 保留(L3) | E18: 成员5
A19: 4 | B19: 门户视觉与手机适配(7.1/7.2) | C19: 直接套模板，不做定制视觉；手机端做到“能看” | D19: 保留 | E19: 成员6
A20: 5 | B20: 站内信与日志(0.5/0.6) | C20: 站内信打开页面时拉取；日志只做记录与查询 | D20: 保留(L3/L2) | E20: 成员2
A21: 6 | B21: 导出(4.4) | C21: 统一同步导出，不做异步任务 | D21: 保留 | E21: 成员3
A22: 7 | B22: 赛事文件(5.3)与门户展示资源(7.2) | C22: 只做上传与列表，不做额外校验与排序 | D22: 保留(P2) | E22: 成员5
A23: 8 | B23: 遴选评分(6.2) | C23: 固定加权平均公式，不做公式可配置 | D23: 保留 | E23: 成员6
A25: 三、明确不在10天内做（放二期）
A26: 序号 | B26: 事项 | C26: 说明 | D26: 来源
A27: 1 | B27: 压测(3倍预估并发)、等保、漏洞扫描 | C27: 10天内只做报名提交50并发冒烟与安全最小集 | D27: V1 A12、A13
A28: 2 | B28: 材料识别(OCR+大模型)与报名材料智能预审 | C28: 预审先用规则校验替代 | D28: V1 B14、C13、C14
A29: 3 | B29: 导入智能映射、战报与直播文案、智能问数、遴选摘要、CMS写作辅助 | C29: 均不属于原244条功能 | D29: V1 B15、D10、D11、E13、E14
A30: 4 | B30: 公示期自动下线与异议入口、评委独立角色、审核流程可视化配置、动态表单设计器 | C30: 原表没有，或属于过度设计 | D30: V1 E03、E05、A09、C05
A31: 5 | B31: 短信通知、WebSocket实时推送、异步导出 | C31: 10天内用站内信、短轮询、同步导出替代 | D31: V1 A11、D05
A33: 四、主要风险与应对
A34: 序号 | B34: 风险 | C34: 应对措施 | D34: 影响 | E34: 负责人
A35: 1 | B35: 组长是唯一前端且零缓冲 | C35: 手写页限5类；标准页由后端生成器自出；门户/CMS/遴选页交成员6；组长不做调度；D4仍落后时，成员6暂停遴选页转帮报名与审核列表页 | D35: 报名与审核页延误会卡住联调 | E35: 组长
A36: 2 | B36: 没有可复用的后台脚手架 | C36: D1前定下脚手架；若没有，10天不成立，应先拆成两期，第一期只做P0 | D36: 整体不可行 | E36: 成员2
A37: 3 | B37: 底座延迟(D1–D4) | C37: 脚手架自带登录先用；文件服务D2交付；其余人用Mock+种子数据并行，接口契约先行 | D37: 全员等待 | E37: 成员2
A38: 4 | B38: 人员主档与报名快照模型对不上 | C38: D1用1小时评审ER总图；身份证为唯一键，报名提交冻结快照 | D38: 后期大面积返工 | E38: 成员3、成员4
A39: 5 | B39: 报名截止日并发 | C39: 提交接口幂等+Nginx限流+关键索引；D9做50并发冒烟；正式压测放二期 | D39: 系统卡顿或丢数据 | E39: 成员3、成员2
A40: 6 | B40: 需求规则不清 | C40: D1确认7项；确认前用可配置默认值，不写死 | D40: 返工 | E40: 组长
A41: 7 | B41: 联调拥堵(D8–D9) | C41: 接口契约先行；每日构建环境；缺陷当天认领；联调清单按三条链路拆分 | D41: 缺陷堆积到D10 | E41: 成员2
A42: 8 | B42: 未成年人敏感信息 | C42: 身份证与手机号加密、脱敏展示；文件私有访问；日志脱敏；问答功能不送个人信息 | D42: 合规与安全事件 | E42: 成员2
A43: 9 | B43: 大模型接口不可用或合规未确认 | C43: 服务端保管密钥；超时降级；开关可一键关闭；政策文本均为公开文件 | D43: 仅影响8.1，不影响主流程 | E43: 成员2
A44: 10 | B44: 人员请假 | C44: 互为备份：成员2↔成员3(底座/审核)，成员4↔成员6(档案/遴选)，成员5↔成员1(赛事录入前后端) | D44: 关键域无人可接 | E44: 组长
